Workbook

Sheet 管理表
A1: 区 | B1: No | C1: 勤務地 | D1: 国籍 | E1: 社員コード | F1: 写真 | G1: フリガナ | H1: 氏名 | I1: 呼名 | J1: 性別 | K1: 生年月日 | L1: 年齢 | M1: 配偶者 | N1: 登録支援機関 | O1: 入社日 | P1: 帰国予定 | Q1: 実習区分 | R1: 住所 | S1: 個・相部屋 | T1: 家賃負担 | U1: 雇用条件書 | V1: カード期限 | W1: 在留カード番号 | X1: 雇用保険番号 | Y1: 自転車渡日 | Z1: 自転車No-防犯 | AA1: 自転車回収日 | AB1: 日本語検定 | AC1: 試験資格 | AD1: 一時退職日 | AE1: 一時帰国From | AF1: 一時帰国To | AG1: 再入社 | AH1: 退職区分 | AI1: 退職日 | AJ1: 帰国費用 | AK1: 部署長 | AL1: 特定1号 保険加入 | AM1: 特定1号 入国日 | AN1: 特定1号保険期間 | AO1: 給与口座 | AP1: 備考 | AQ1: 在留カード表裏 | AR1: パスポート | AS1: 特定保険証券 | AT1: 通帳 | AU1: 保険証 | AV1: 日本語合格 | AW1: 特定２号合格 | AX1: 免許関係 | AY1: その他１（写真） | AZ1: その他２（写真） | BA1: その他１（ファイル） | BB1: その他２（ファイル）
B2: 1 | C2: 津吉 | D2: ベトナム | E2: 07011401 | G2: ホアン ティ フォン | H2: HOANG THI HUONG | I2: ホアンフォン | J2: 女 | K2: 31861 | L2: =DATEDIF(K2,TODAY(),"Y") -> 39 | N2: 中四国 | O2: 43040 | P2: 2022/11 | Q2: 技能実習3号 | R2: 松山市津吉町535-1コーポ津吉1-2 | V2: 44893 | W2: ＤＸ30707722ＰＣ | X2: 5100-318356-1 | AH2: 退職 | AI2: 44831
B3: 2 | C3: 津吉 | D3: ベトナム | E3: 07011502 | G3: ドー ティ ミー ハイン | H3: DO THI MI HANH | I3: ハイン | J3: 女 | K3: 32774 | L3: =DATEDIF(K3,TODAY(),"Y") -> 36 | N3: 中四国 | O3: 43040 | P3: 2022/11 | Q3: 技能実習3号 | R3: 松山市津吉町535-1コーポ津吉1-2 | V3: 44893 | W3: ＤＸ89886995ＰＣ | X3: 5100-318488-1 | AH3: 退職 | AI3: 44879
A4: =_xludf.IMAGE("F96",1) -> #NAME? | B4: 3 | C4: 津吉 | D4: ベトナム | E4: 07011602 | F4: /appsheet/photograph/3.写真.030343.jpg | G4: グエン ビック フーン | H4: NGUYEN BICH PHUONG | I4: フーン | J4: 女 | K4: 31664 | L4: =DATEDIF(K4,TODAY(),"Y") -> 39 | M4: 有 | N4: 中四国 | O4: 43040 | P4: 2027/01 | Q4: 特定技能１号 | R4: 松山市津吉町535-1コーポ津吉1-2 | S4: 個 | T4: 20000 | U4: 45887 | V4: 46327 | W4: UH17492757PC | X4: 5100-318256-3 | Z4: 通勤は自転車B-0128657 白26ｲﾝﾁABELIA 買い物と外出時は ｱｼｽﾄ自転車（知人から貰った） | AA4: 2026/02/13 | AE4: 45711 | AF4: 45732 | AH4: 退職 | AI4: 46066 | AJ4: 広島→ハノイ 79,500- 空港までは自己で行くが荷物２個は空港まで会社負担 | AK4: 帰国 飛行機代会社負担 | AL4: 〇 | AM4: 44866 | AN4: 2025/8/1～2026/7/31 ※2026年に帰国予定の 為、本人より1年間の契約希望 | AO4: ひめぎん 末広町支店 | AP4: 2/20まで出勤・3/17より出勤 2026/2月に退職して帰国したい申し出。 新開工場長へ連絡済み。帰りの飛行機代を確認依頼。 帰りの飛行機代は会社負担（専務了承済） 2026/2/13退職 最終出勤日1/22（1/23～有給消化） 2/14退寮 2/13 給料現金払い 1/23～夫のところへ行くため、1/23～2/14までの光熱費 は￥1000請求（尾崎さんより1/14） 2/9口座解約、転出届予定。
B5: 4 | C5: 津吉 | D5: ベトナム | E5: 07011603 | G5: ヴー ティ アイン | H5: VU THI ANH | I5: アイン | J5: 女 | K5: 35781 | L5: =DATEDIF(K5,TODAY(),"Y") -> 28 | N5: 中四国 | O5: 43040 | P5: 2027/10 | Q5: 特定技能１号 | R5: 松山市津吉町535-1コーポ津吉1-2 | V5: 45231 | W5: TJ66354580PA | X5: 5100-318538-2 | AH5: 退職 | AI5: 45127
B6: 5 | C6: 本社 | D6: ベトナム | E6: 07001701 | G6: ブイ ティ チン | H6: BUI THI CHINH | I6: チン | J6: 女 | K6: 34817 | L6: =DATEDIF(K6,TODAY(),"Y") -> 30 | N6: 中四国 | O6: 43162 | P6: 2029/06 | Q6: 特定技能１号 | R6: 和泉北1-20-28アトムスカイマンション401 | S6: 個 | T6: 20000 | V6: 45483 | W6: NP48961811PA | X6: 特定技能 23.7/10～ | Z6: 番号なし 福岡47－え5316 | AA6: 2024/04/21 小栗工場裏 | AB6: N3:2021.7月 | AE6: 44958 | AF6: 45000 | AH6: 退職 | AI6: 45402 | AJ6: 2024.4月完全帰国 帰国費用会社負担 | AP6: 24.4.20退職決定（4/17最終出勤日、4/18～4/20は有休） 4/22退寮
B7: 6 | C7: 本社 | D7: ベトナム | E7: 07001502 | G7: チャン ティ ガー | H7: TRAN THI NGA | I7: ガー | J7: 女 | K7: 32727 | L7: =DATEDIF(K7,TODAY(),"Y") -> 36 | N7: 中四国 | O7: 43435 | P7: 2023/11 | Q7: 技能実習3号 | R7: 小栗1丁目3-30ﾋﾟｯｺﾛｶｽﾀｰﾆｬ308 | V7: 45273 | W7: TJ69040729PC | X7: 5103-260930-7 | AH7: 退職 | AI7: 45198
B8: 7 | C8: 本社 | D8: ベトナム | E8: 07001509 | F8: =_xludf.IMAGE(F9) -> #NAME? | G8: ブイ ティ ヴィエトザン | H8: BUI THI VIET GIANG | I8: ザン | J8: 女 | K8: 35832 | L8: =DATEDIF(K8,TODAY(),"Y") -> 28 | N8: 中四国 | O8: 43435 | P8: 2023/11 | Q8: 技能実習3号 | R8: 雄郡1丁目6-2ｱﾙﾄ雄郡西405 | V8: 45273 | W8: TJ53898721PC | X8: 5103-260928-3 | AH8: 退職 | AI8: 45259
B9: 8 | C9: 本社 | D9: ベトナム | E9: 07001612 | F9: /appsheet/photograph/小栗_タム_20240424.jpg | G9: グエン ティ タム | H9: NGUYEN THI TAM | I9: タム | J9: 女 | K9: 33800 | L9: =DATEDIF(K9,TODAY(),"Y") -> 33 | M9: 無 | N9: 中四国 | O9: 43435 | P9: 2025/09 | Q9: 特定技能１号 | R9: 和泉北1-20-28アトムスカイマンション304 | S9: 相1 | T9: 10000 | U9: 45383 | V9: 45912 | W9: SA28686623PA | X9: 5103-260925-5 | Z9: 1966ーB-0091966 | AB9: N4 2024/07/07 | AD9: 45311 | AE9: 45311 | AF9: 45342 | AG9: 45343 | AH9: 退職 | AI9: 45646 | AJ9: 実習終了後完全帰国 12/23 松山→成田15,000 宿泊 12/24 成田→ハノイ80,000 | AP9: 2024.6.12～社員コード変わる済（特定活動になるため） 2024.6.12～9/152実習3号→特定活動 9/12～特定技能へ
B10: 9 | C10: 本社 | D10: ベトナム | E10: 07001611 | F10: /appsheet/photograph/小栗_ミン_20240424.jpg | G10: ブイ ティ ミン | H10: BUI THI MINH | I10: ミン | J10: 女 | K10: 36245 | L10: =DATEDIF(K10,TODAY(),"Y") -> 27 | M10: 夫婦 | N10: 中四国 | O10: 43435 | P10: 2025/09 | Q10: 特定技能１号 | R10: 和泉北1-20-28アトムスカイマンション305 | S10: 夫婦 | T10: 20000 | U10: 45870 | V10: 46294 | W10: UH54552117PC | X10: 5103-260929-6 | Z10: 返却済 宮内工場長の自転車を乗っている | AB10: N4 2024/07/07 | AE10: 45271 | AF10: 45311 | AL10: 〇 | AM10: ２018/10/30 | AN10: 2025/8/1～2029/9/30 | AO10: 伊予銀 | AP10: ※特定技能申請の為、ﾊﾟｽﾎﾟｰﾄと在留ｶｰﾄﾞは中四国預かり（6/13朴さんより） 2024.6.12～社員コード変わる済（特定活動になるため） 2024.6.12～9.12実習3号→特定活動 9/12～特定技能へ ※特定活動（6ヵ月）申請しその期間に特定技能へ変更予定。 2026/5/4出産予定日 一時帰国し出産予定。2026/3/24～6/29産休 6/30～2027/5/3育休
B11: 10 | C11: 本社 | D11: ベトナム | E11: 07001613 | F11: /appsheet/photograph/10.写真.032947.jpg | G11: グエン ティ ロアン | H11: NGUYEN THI LOAN | I11: ロアン | J11: 女 | K11: 31701 | L11: =DATEDIF(K11,TODAY(),"Y") -> 39 | M11: 有 | N11: 中四国 | O11: 43435 | P11: 2025/09 | Q11: 特定技能１号 | R11: 和泉北1-20-28アトムスカイマンション403 | S11: 個1 | T11: 20000 | U11: 45870 | V11: 46294 | W11: UH51964624PC | X11: 5103-260926-8 | Z11: 1968-B-0091968 2024/08/27自転車変更 7912(1596)赤へ 2025/08/27変更 B-0246665-1008 | AD11: 45317 | AE11: 2024/01/27 2026/5月頃 | AF11: 2024/02/27 2026/7月頃 | AG11: 45350 | AL11: 〇 | AM11: 43403 | AN11: 2025/8/1～2029/5/31 | AO11: 伊予銀 湊町支店 | AP11: ※特定技能申請の為、ﾊﾟｽﾎﾟｰﾄと在留ｶｰﾄﾞは中四国預かり（6/13朴さんより） 2024.6.12～社員コード変わる済（特定活動になるため） 2024.6.12～9/152実習3号→特定活動 9/12～特定技能へ ※特定活動（6ヵ月）申請しその期間に特定技能へ変更予定。 2022.7.18一時退職8/9～一時帰国 2024.1.26一時退職 2025/10/4 2～3年前から週に5日程下痢が続いているため、窪田クリニックを受診。便検査の結果、病原性大腸菌O-18が見つかり、ベロ毒素の検査結果は陰性。（陽性であれば保健所に届け出が必要とのこと）。除菌のため、抗生物質の薬を5日服用し、5日後に再度便検査を病院でする予定。 | AT11: /appsheet/photograph/07001613.通帳.040920.jpg
B12: 11 | C12: 協同本社 | D12: ベトナム | E12: 17001003 | G12: チャン ティ トゥー ヒエン転籍 | H12: TRAN THI THU HIEN | I12: ヒエン | J12: 女 | K12: 33673 | L12: =DATEDIF(K12,TODAY(),"Y") -> 34 | N12: 中四国 | O12: 43627 | P12: 2024/06 | Q12: 技能実習3号 | R12: 和泉北1-20-28アトムスカイマンション403 | V12: 45116 | W12: TJ09931713PC | X12: 5105-142066-5 | Z12: 1905-1056 | AA12: 小栗工場裏 | AH12: 退職 | AI12: 45066 | AP12: 2025年頃日本に戻って技能実習を再開したいとの希望あり
B13: 12 | C13: 本社 | D13: ベトナム | E13: 07001614 | F13: /appsheet/photograph/12.写真.224547.jpg | G13: ホアン ティ チャン | H13: HOANG THI TRANG | I13: チャン | J13: 女 | K13: 34922 | L13: =DATEDIF(K13,TODAY(),"Y") -> 30 | N13: 中四国 | O13: 43627 | P13: 2025/09 | Q13: 特定技能１号 | R13: 和泉北1-20-28アトムスカイマンション403 | S13: 個2 | T13: 20000 | U13: 45870 | V13: 46294 | W13: UH80838380PC | X13: 5105-142112-5 | Z13: 2021/01購入 なし-B-0188562 | AE13: 44760 | AF13: 44803 | AL13: 〇 | AM13: 43594 | AN13: 2025/8/1～2029/5/31 | AO13: 伊予銀 | AP13: ※特定技能申請の為、ﾊﾟｽﾎﾟｰﾄと在留ｶｰﾄﾞは中四国預かり（6/13朴さんより） 2024.6.12～9/12 実習3号→特定活動 9/12～特定技能へ ※特定活動（6ヵ月）申請しその期間に特定技能へ変更予定。 2024.6.12～（協同→中温へ転籍）
B14: 13 | C14: 協同本社 | D14: ベトナム | G14: チャン ティ フォン | H14: TRAN THI HUONG | I14: チャンフォン | J14: 女 | K14: 32356 | L14: =DATEDIF(K14,TODAY(),"Y") -> 37 | N14: 中四国 | O14: 43627 | Q14: 技能実習2号 | R14: 和泉北1-20-28アトムスカイマンション402 | V14: 44327 | W14: LD29267624PC | X14: 5105-141994-8 | AH14: 退職 | AI14: 44679
B15: 14 | C15: 本社 | D15: ベトナム | E15: 07001404 | G15: チャン ティ フォン | H15: TRAN THI HUONG | I15: フォン | J15: 女 | K15: 36187 | L15: =DATEDIF(K15,TODAY(),"Y") -> 27 | N15: 中四国 | O15: 43879 | P15: 2023/01 | Q15: 技能実習2号 | R15: 和泉北1-20-28アトムスカイマンション305 | V15: 44984 | W15: TJ51126887PC | X15: 5106-445108-4 | AH15: 退職 | AI15: 44941
B16: 15 | C16: 津吉 | D16: ベトナム | E16: 07011405 | G16: グエン ティ ゴック タオ | H16: NGUYEN THI NGOC THAO | I16: タオ | J16: 女 | K16: 34452 | L16: =DATEDIF(K16,TODAY(),"Y") -> 31 | N16: 中四国 | O16: 43729 | P16: 2022/08 | Q16: 技能実習2号 | R16: 松山市津吉町535-1コーポ津吉1-6 | V16: 44794 | W16: DX17958926PC | X16: 5105-743699-4 | AH16: 退職 | AI16: 44793
B17: 16 | C17: 津吉 | D17: ベトナム | E17: 07011504 | G17: ファム ティ ヒエン | H17: PHAM THI HIEN | I17: ファムヒエン | J17: 女 | K17: 36585 | L17: =DATEDIF(K17,TODAY(),"Y") -> 26 | N17: 中四国 | O17: 43729 | P17: 2024/08 | Q17: 技能実習3号 | R17: 松山市津吉町535-1コーポ津吉1-6 | T17: 20000 | U17: 44690 | V17: 45587 | W17: NP60084115PC | X17: 5105-743702-4 | Z17: 自身で購入 会社支給 管理番号なし B-0128655 買い物等は自転車使用 | AA17: 45394 | AC17: 缶詰巻締上級 2024/09/12 | AE17: 44958 | AF17: 45000 | AH17: 退職 | AI17: 45568 | AJ17: 実習終了帰国 松山→ベトナム ６３，６００円 | AP17: 2024.10.3実習3号終了が正しい 実習終了にて帰国予定 有給１６日在留カード期限10/22だが、10/3が実習終了のため9/9最終出勤、10/3退職 10/4退寮 現金支払い
B18: 17 | C18: 津吉 | D18: ベトナム | E18: 07011402 | G18: グエン ティ トゥー | H18: NGUYEN THI THU | I18: トゥー | J18: 女 | K18: 31954 | L18: =DATEDIF(K18,TODAY(),"Y") -> 38 | N18: 中四国 | O18: 43729 | P18: 2022/08 | Q18: 技能実習2号 | R18: 松山市津吉町535-1コーポ津吉1-6 | V18: 44794 | W18: DX99865766PC | X18: 5105-743700-9 | AH18: 退職 | AI18: 44793
B19: 18 | C19: 本社 | D19: ベトナム | E19: 07001403 | G19: グエン ティ トゥー | H19: NGUYEN THI THU | I19: トゥー | J19: 女 | K19: 33508 | L19: =DATEDIF(K19,TODAY(),"Y") -> 34 | N19: 中四国 | O19: 43879 | P19: 2023/01 | Q19: 特定技能１号 | R19: 和泉北1-20-28アトムスカイマンション305 | V19: 45332 | W19: NP29436386PA | X19: 5106-445109-7 | AH19: 退職 | AI19: 45066
B20: 19 | C20: 津吉 | D20: ベトナム | E20: 07011613 | F20: /appsheet/photograph/19.写真.032434.jpg | G20: ファム ティ チン | H20: PHAM THI CHINH | I20: チン | J20: 女 | K20: 33243 | L20: =DATEDIF(K20,TODAY(),"Y") -> 35 | M20: 夫婦 | N20: 中四国 | O20: 43729 | P20: 2029/08 | Q20: 特定技能１号 | R20: 松山市上野町774番地ビレッジハウス松山上野1-303 | S20: 夫婦 | T20: 0 | U20: 45912 | V20: 46360 | W20: UH90854712PC | X20: 5105-743701-1 | Z20: ご主人のバイクで通勤 会社支給 管理番号なし B-0128654 白26ｲﾝﾁ | AA20: 通勤方法確認書 には通勤、買い物も 会社の自転車使用 と記載あり | AE20: 45707 | AF20: 45707 | AH20: 育児休暇中 | AJ20: 2025/03/11帰国費用 広島⇔ハノイ74,300円 半額負担し、特定終了後は 負担しない | AL20: × | AN20: 自転車保険 2026/09/15 | AP20: ビレッジハウス 個人で契約するとのこと 妊娠のため2025.9月末頃？～産休（予定日11/7）2025.5.30出産で9月頃退職後一時帰国予定。（子供が1才になるまで）再度中温へ戻りたいとの希望あり。→中四国朴さんより、日本で出産すると本人が言っているとのこと。寮は次が確定しているため、再度確認依頼済。 2024/12/04～特定技能 2024/10/04～特定活動 2024.10.20 実習3号終了予定 130ズオンデタオが夫 2024/09/18 特定技能へ申請手続き 2024/09/25コーポ津吉1-6よりビレッジ2-503へ引越→通勤届済 2025.9.5引越 ビレッジ1-303へ（チン名義で借りる） 2025.9.27～育児休暇 2026/10/20までは確定 2025.11.4帝王切開予定 2025.10/31出産 | AQ20: /appsheet/photograph/07011613.在留カード表裏.072221.pdf
B21: 20 | C21: 津吉 | D21: ベトナム | E21: 07011506 | G21: カオ ティ トム | H21: CAO THI THOM | I21: トム | J21: 女 | K21: 36177 | L21: =DATEDIF(K21,TODAY(),"Y") -> 27 | N21: 中四国 | O21: 43762 | P21: 2024/09 | Q21: 技能実習3号 | R21: 松山市津吉町535-1コーポ津吉1-6 | V21: 45221 | W21: TJ09914475PC | X21: 5105-880527-2 | AH21: 退職 | AI21: 45158
B22: 20 | D22: ベトナム | G22: ズオン トアン タン （チン、タオの赤ちゃん） | H22: DUONG TOAN THANG | J22: 男 | K22: 45961 | L22: 0 | Q22: 特定活動 | R22: 松山市上野町774番地ビレッジハウス松山上野1-303 | S22: チン、タオの子供 | V22: 46373 | W22: UH90942141PC | AL22: ― | AM22: ― | AN22: ― | AP22: こちらでチンの更新と一緒に在留カード更新する｡
B23: 21 | C23: 津吉 | D23: ベトナム | E23: 07011764 | G23: グエン ヴァン ハオ | H23: NGUYEN VAN HAO | I23: ハオ | J23: 男 | K23: 34732 | L23: =DATEDIF(K23,TODAY(),"Y") -> 31 | N23: 中四国 | O23: 44616 | P23: ? | Q23: 特定活動 | R23: 松山市上野町774番地ビレッジハウス松山上野2-508 | V23: 44964 | W23: TJ88198592RA | X23: 5098-636935-8 | AH23: 退職 | AI23: 44956
B24: 22 | C24: 津吉 | D24: ベトナム | E24: 07011601 | G24: ビー ティー ジェム フォン | H24: VI THI DIEM HUONG | I24: ビーフォン | J24: 女 | K24: 34241 | L24: =DATEDIF(K24,TODAY(),"Y") -> 32 | N24: 中四国 | O24: 42655 | P24: 2024/09 | Q24: 特定技能１号 | R24: 松山市津吉町535-1コーポ津吉1-2 | V24: 45207 | W24: TJ92560142PA | X24: 5097-085709-2 | AH24: 退職 | AI24: 45005
B25: 23 | C25: 津吉 | D25: ベトナム | G25: グエン ティ チャム フェン | H25: NGUYEN THI TRAM HUYEN | I25: チャムフェン | J25: 女 | K25: 33824 | L25: =DATEDIF(K25,TODAY(),"Y") -> 33 | N25: ポエム | O25: 44013 | P25: ? | Q25: 特定活動 | R25: 津吉町535-1コーポ津吉2-4 | V25: 44735 | W25: DX99566980PC | X25: 5105-699781-1 | AH25: 退職 | AI25: 44712
B26: 24 | C26: 津吉 | D26: ベトナム | E26: 07011761 | G26: ホアン ティ ハン★ | H26: HOANG THI HAN | I26: ハン | J26: 女 | K26: 32890 | L26: =DATEDIF(K26,TODAY(),"Y") -> 36 | N26: ポエム | O26: 44013 | Q26: 特定活動 | R26: 津吉町535-1コーポ津吉2-4 | V26: 44857 | W26: ＴＪ04286685PC | X26: 5105-385457-3 | AH26: 退職 | AI26: 44854
B27: 25 | C27: 津吉 | D27: ベトナム | E27: 07011762 | G27: ヴー ティ・ホアン★ | H27: VU THI HOAN | I27: ホアン | J27: 女 | K27: 32353 | L27: =DATEDIF(K27,TODAY(),"Y") -> 37 | N27: ポエム | O27: 44013 | P27: ? | Q27: 特定活動 | R27: 津吉町535-1コーポ津吉2-4 | V27: 44857 | W27: ＴＪ39383067PC | X27: 5105-385458-6 | Z27: 2104? | AH27: 退職 | AI27: 44854
B28: 26 | C28: 津吉 | D28: ベトナム | E28: 07011606 | F28: /appsheet/photograph/26.写真.001347.jpg | G28: ヴー ティ ホアン | H28: VU THI HOAN | I28: ホアン | J28: 女 | K28: 32353 | L28: =DATEDIF(K28,TODAY(),"Y") -> 37 | M28: 有 | N28: 中四国 | O28: 45111 | P28: 2028/06 | Q28: 特定技能１号 | R28: 松山市津吉町535-1コーポ津吉1-2 | S28: 個 | T28: 20000 | U28: 45734 | V28: 46206 | W28: UH16081560PA | Z28: 2104 通勤、買い物も会社 支給の自転車使用 | AC28: 2026/1月２号試験希望_統括より | AD28: 46101 | AE28: 2024/07/01 2026/01/24 | AF28: 2024/08/01 2026/03/21 | AH28: 一時退職 | AL28: 〇 | AM28: 45110 | AN28: 2025/8/1～2028/6/30 | AP28: 24.7/3頃～8/5頃一時帰国 新開工場長へ申請あり4/24 →中四国 からの日程の連絡待ち。→6/30～7/31確定（6/19中四国より） 本人からの休暇届けは7/1～8/1一時帰国（全て有給申請）となって いるため、中四国廣瀬さんへ確認依頼済（6/28中に） 一時帰国後8/6以降順風会で健診予定 24.4月分～ﾎｱﾝﾃｨﾊﾝが入寮したら家賃2万→1万へ 2026.1月 特定2号受験予定 2025/11/7特定2号試験終了後、２月初めから、２ヶ月一時帰国したい申し出あり。水沼さん了承。 | AW28: /appsheet/photograph/07011606.特定２号合格.011012.pdf
B29: 27 | C29: 津吉 | D29: ベトナム | E29: 07011763 | G29: チャン ティ ホアン リェン | H29: TRAN THI HOANG LIEN | I29: リエン | J29: 女 | K29: 30163 | L29: =DATEDIF(K29,TODAY(),"Y") -> 43 | N29: ポエム | O29: 44013 | P29: ? | Q29: 特定活動 | R29: 松山市津吉町535-1コーポ津吉1-6 | V29: 44857 | W29: ＴＪ53602521PC | X29: 5105-385461-2 | AH29: 退職 | AI29: 44854
B30: 28 | C30: 本社 | D30: ベトナム | E30: 07001609 | F30: /appsheet/photograph/IDPhoto_20240711_マイン.jpg | G30: トー マイン トゥ | H30: TO MANH TU | I30: マイン | J30: 男 | K30: 34747 | L30: =DATEDIF(K30,TODAY(),"Y") -> 31 | N30: 中四国 | O30: 44119 | P30: 2028/08 | Q30: 特定技能１号 | R30: 小栗1丁目3-30ﾋﾟｯｺﾛｶｽﾀｰﾆｬ308 | S30: 個 | T30: 20000 | U30: 45484 | V30: 45912 | W30: SA48074257PA | X30: 5109-022627-2 | Z30: 2020/10購入 B-0177518-1040 | AD30: 45306 | AE30: 45306 | AF30: 45341 | AG30: 45343 | AH30: 退職 | AI30: 45904 | AJ30: 帰国 | AL30: ― | AN30: ― | AO30: ― | AP30: 特定技能1号期間更新中 24.7.11 2025.8月か9月頃に帰国希望（工場長より） 2025/08/31ピッコロ解約し、9/5退職9/9頃帰国 9/1～9/5アトム504 9/4退職、9/5退寮 有給残10日あり ※最終出勤日8/27 9/5現金払い
B31: 29 | C31: 本社 | D31: ベトナム | E31: 07001629 | F31: /appsheet/photograph/IDPhoto_20240711_ヴィエット.jpg | G31: チャン ヴァン ヴィエット | H31: TRAN VAN VIET | I31: ヴィエット | J31: 男 | K31: 32955 | L31: =DATEDIF(K31,TODAY(),"Y") -> 36 | N31: 中四国 | O31: 44119 | P31: 2028/08 | Q31: 特定技能１号 | R31: 和泉北1-20-28アトムスカイマンション504 | S31: 相1 | T31: 20000 | U31: 2025/08/01 2026/01/31 | V31: 46294 | W31: UH63950753PC | X31: 5109-022666-1 | Z31: 2020/10購入 紛失17000002-B-0177519 新888-B-0143840-1653 | AA31: 5/30立花駅にて盗難 6/3市駅前交番届出 | AD31: 46015 | AE31: 46016 | AF31: 46055 | AG31: 46056 | AJ31: 2025/12/25-2026/2/2 関西国際空港⇔ハノイ 115,800円 | AL31: ― | AN31: 自転車保険 2026/09/15 | AO31: 伊予銀 三津浜支店 | AP31: 特定技能1号期間更新中 24.7.11 6/3 10:01受理 市駅前交番にて 5/30自転車盗難の申出。鍵が故障により施錠しておらずとの申し出。6/3組合に5,000円徴収依頼 6/4￥5000支払済 2025/10/8伊予銀 三津浜支店 ワタナベさんより連絡あり。在留ｶｰﾄﾞ更新後のコピーの提出がまだ。10/17 2025/12/25～2026/02/02一時帰国希望（宮内工場長より） 2025/12/24一時退職 12/25～2026/2/2一時帰国 2026/2/3再入社 社員ｺｰﾄﾞ変更済 | AQ31: /appsheet/photograph/07001605.在留カード表裏.003116.pdf
B32: 30 | C32: 本社 | D32: ベトナム | E32: 07001610 | F32: /appsheet/photograph/IDPhoto_20240711_ダット.jpg | G32: グエン ヒュー タイン ダット | H32: NGUYEN HUU THANH DAT | I32: ダット | J32: 男 | K32: 37255 | L32: =DATEDIF(K32,TODAY(),"Y") -> 24 | M32: 夫婦 | N32: 中四国 | O32: 44119 | P32: 2028/08 | Q32: 特定技能１号 | R32: 松山市末広町5-14三和ﾏﾝｼｮﾝ末広201 | S32: 夫婦 | T32: 21500 | U32: 46082 | V32: 46294 | W32: UH42724630PC | X32: 5109-022610-8 | Z32: 2020/10購入 17000003 B-0177520 | AB32: N3 2024/12/01 | AD32: 45306 | AE32: 45306 | AF32: 45352 | AG32: 45355 | AL32: 〇 | AM32: 45181 | AN32: 2025/8/1～2028/8/31 | AO32: 伊予銀 | AP32: 特定技能1号期間更新中 24.7.11 2024.6.21～ｱﾄﾑ504→三和ﾏﾝｼｮﾝ末広201へ引越 6/26住所変更済（中四国で） 家賃￥21500/人。家具家電は会社負担 奥さんｱｲﾝと一緒に住む 2025/7/24一時帰国から戻ってから在留ｶｰﾄﾞ更新予定⇒済9/29 2026.1月 特定2号受験予定 | AT32: /appsheet/photograph/07001610.通帳.042824.pdf | AW32: /appsheet/photograph/07001610.特定２号合格.010117.pdf
B33: 31 | C33: 本社 | D33: ベトナム | E33: 07001406 | G33: ダン ティ タイン トゥイ | H33: DANG THI THANH THUY | I33: ダン | J33: 女 | K33: 36097 | L33: =DATEDIF(K33,TODAY(),"Y") -> 27 | N33: 中四国 | O33: 43879 | P33: 2023/01 | Q33: 技能実習2号 | R33: 和泉北1-20-28アトムスカイマンション305 | V33: 44953 | W33: TJ41491013PC | X33: 5106-445113-6 | AH33: 退職 | AI33: 44941
B34: 32 | C34: 本社 | D34: ベトナム | E34: 07001407 | G34: ダオ ティ トゥー フエン | H34: DAO THI THU HUYEN | I34: ダオ | J34: 女 | K34: 34487 | L34: =DATEDIF(K34,TODAY(),"Y") -> 31 | N34: 中四国 | O34: 43879 | P34: 2023/01 | Q34: 技能実習2号 | R34: 和泉北1-20-28アトムスカイマンション304 | V34: 44953 | W34: TJ48438123PC | X34: 5106-445107-1 | AH34: 退職 | AI34: 44915 | AP34: 22.12/20 退職 12/23 帰国
B35: 33 | C35: 本社 | D35: ベトナム | E35: 07001402 | G35: ハー ティ ソン | H35: HA THI SON | I35: ソン | J35: 女 | K35: 33354 | L35: =DATEDIF(K35,TODAY(),"Y") -> 34 | N35: 中四国 | O35: 43879 | P35: 2023/01 | Q35: 技能実習2号 | R35: 和泉北1-20-28アトムスカイマンション304 | V35: 44953 | W35: TJ44753516PC | X35: 5106-445112-3 | AH35: 退職 | AI35: 44941
B36: 34 | C36: 本社 | D36: ベトナム | E36: 07001401 | G36: グエンティ ミン フォン | H36: NGUYEN THI MINH HUONG | I36: グエン | J36: 女 | K36: 35901 | L36: =DATEDIF(K36,TODAY(),"Y") -> 28 | N36: 中四国 | O36: 43879 | P36: 2023/01 | Q36: 技能実習2号 | R36: 和泉北1-20-28アトムスカイマンション305 | V36: 44953 | W36: TJ57789188PC | X36: 5106-445110-8 | AH36: 退職 | AI36: 44941
B37: 35 | C37: 津吉 | D37: ベトナム | E37: 07011605 | G37: ファム ティ リン | H37: PHAM THI LINH | I37: リン | J37: 女 | K37: 36662 | L37: =DATEDIF(K37,TODAY(),"Y") -> 25 | N37: 中四国 | O37: 43879 | P37: 2028/02 | Q37: 特定技能１号 | R37: 松山市津吉町535-1コーポ津吉1-6 | T37: 20000 | V37: 45716 | W37: SA26542494PA | X37: 5106-445114-9 | Z37: 自身で購入（ｱｼｽﾄ自転車）通勤使用 ﾀﾞｲｷで購入 書類紛失の為 防犯登録等不明 会社支給 管理番号なし B-0128657会社の自転車は時々使用 | AE37: 45324 | AF37: 45346 | AH37: 退職 | AI37: 45513 | AP37: 2024.8.14退職希望とのことで新開工場長より（7/1）2024.2/2～2/24一時帰国 特定技能23.2/28～ 23.3/21～津吉へ 最終8/9退職 8/15退寮
B38: 36 | C38: 本社 | D38: ベトナム | E38: 07001617 | F38: /appsheet/photograph/36.写真.225148.jpg | G38: グエン タイン ド― | H38: NGUYEN THANH DO | I38: ドー | J38: 男 | K38: 33529 | L38: =DATEDIF(K38,TODAY(),"Y") -> 34 | M38: 有 | N38: 中四国 | O38: 44221 | P38: 2028/12 | Q38: 特定技能１号 | R38: 和泉北1-20-28アトムスカイマンション504 | S38: 相2 | T38: 20000 | U38: 45912 | V38: 46377 | W38: UH64477231PC | X38: 5109-504178-2 | Z38: 2021/01購入 8561 B-0188561-1188 | AE38: 45677 | AF38: 45721 | AG38: 45723 | AJ38: 関空⇔ハノイ 98,300-会社負担 | AL38: ― | AN38: ― 自転車保険加入済 2026/2/1～2027/2/1 1年間 | AQ38: /appsheet/photograph/07001617.在留カード表裏.072440.pdf | AR38: 管理表_Files_/07001617.パスポート.003113.pdf
B39: 37 | C39: 本社 | D39: ベトナム | E39: 07001409 | G39: ハー ティ タイン ハン | H39: HA THI THANH HANG | I39: ハン | J39: 女 | K39: 36747 | L39: =DATEDIF(K39,TODAY(),"Y") -> 25 | N39: 中四国 | O39: 44221 | P39: 2028/12 | Q39: 技能実習2号 | R39: 和泉北1-20-28アトムスカイマンション304 | V39: 45281 | W39: TJ53670164PC | X39: 5109-504268-5 | AH39: 退職 | AI39: 45275
B40: 38 | C40: 津吉 | D40: ベトナム | E40: 07011611 | G40: レー ティ ニュン | H40: LE THI NHUNG | I40: ニュン | J40: 女 | K40: 36713 | L40: =DATEDIF(K40,TODAY(),"Y") -> 25 | N40: 中四国 | O40: 44221 | P40: 2028/12 | Q40: 特定技能１号 | R40: 津吉町535-1コーポ津吉2-4 | T40: 20000 | V40: 45647 | W40: NP14928533PA | X40: 5109-504384-3 | Z40: ｱｲｽﾄ自転車 B-0266737 青 ﾀｹﾀﾞ403 SUISUI 車体番号CFS22060439 | AA40: 会社支給の自転車 は使用していない | AD40: 45324 | AE40: 45324 | AF40: 45371 | AG40: 45372 | AH40: 退職 | AI40: 45513 | AP40: 2024.8.14退職希望とのこと新開工場長より（7/1） 一時退職の為社員コード変わる2023.3/21～済 24.3.21～1人へ（家賃2万へ） 3/21再入社 3/21は欠勤 最終8/9退職 8/15退寮
...

Sheet 履歴
A1: 連番 | B1: 日付 | C1: 時間 | D1: 登録者 | E1: 実習生 | F1: 場所 | G1: 申請区分 | H1: 完了区分 | I1: 登録画像１－１ | J1: 登録画像１－２ | K1: 登録記事 | L1: 対応１日付 | M1: 対応１時間 | N1: 対応者１ | O1: 対応画像１ー１ | P1: 対応画像１－２ | Q1: 対応１記事 | R1: 対応２日付 | S1: 対応２時間 | T1: 対応者２ | U1: 対応画像２ー１ | V1: 対応画像２－２ | W1: 対応２記事 | X1: 対応３日付 | Y1: 対応３時間 | Z1: 対応者３ | AA1: 対応画像３ー１ | AB1: 対応画像３－２ | AC1: 対応３記事 | AD1: 対応４日付 | AE1: 対応４時間 | AF1: 対応者４ | AG1: 対応画像４ー１ | AH1: 対応画像４－２ | AI1: 対応４記事 | AJ1: 対応５日付 | AK1: 対応５時間 | AL1: 対応者５ | AM1: 対応画像５ー１ | AN1: 対応画像５－２ | AO1: 対応５記事 | AP1: 備考
A2: 1 | B2: 45958 | C2: 0.37100694 | D2: 池内 | E2: 07013662 | F2: ビレッジ4-502 | G2: 病院 | H2: 完了 | L2: 45958 | N2: 池内 | O2: 履歴_Images/1.対応画像１ー２.015505.jpg | Q2: 10.26から体調不良 10.28かどた内科にて受診でコロナ陽性 金曜日まで自宅療養
A3: 2 | B3: 45959 | C3: 0.63690972 | D3: 池内 | E3: 07013675 | F3: ビレッジ3-501 | G3: 病院 | H3: 対応中 | K3: 10/29にチンティアから、11/12にどい心療内科へ連れてってほしいと相談。（最近眠れない、涙が出る。などの症状）本人が11：50診察予約している。チンティアのおばが通訳として病院に同行予定。 | L3: 45961 | M3: 0.51388889 | N3: 尾崎 | Q3: 新開工場長より、昨日、タブレット入力ミスを他の実習生に指摘され更衣室で泣いてた。その時に精神科受診の話を聞いた。本日、休み。明日も休むようなら様子を確認すると伝える。11.1_10時自宅にて池内さん尾崎で話し、落ち着いた様子。とりあえず、月曜日から仕事にはいく。ブイにも話しなくていいとのこと。また何かあれば、連絡依頼。11/4に11/3,11/4出勤確認。 | R3: 45973 | T3: 池内 | W3: 11/12どい心療内科受診。3か月ほど前から不安症状あり。他人からどう見られているのかとても気にしてしまい過剰に不安になる。失敗するのが怖く、色々考えて集中できない。10日分の薬をもらい11/22に再度受診予定。11月頭の実習生に怒られた件も少しトラウマになっているので、今後のチーム組むときにできれば配慮をしてほしいと工場長に相談した。 | AC3: 11/22経過観察。インドネシアにいるときにも心療内科かかってたらしい。合う薬模索中。次回12/5 10:00~ | AP3: 12/22済・次回1/23 9:50～
A4: 3 | B4: 45960 | C4: 0.4099537 | D4: 尾崎 | E4: 07013641 | G4: 帰国 | H4: 完了 | K4: 新開工場長より、2026/3/13より2ヶ月ぐらい、自身の結婚のため帰国の申し出。日程の調整確認依頼 | L4: 45960 | M4: 0.45362269 | N4: 尾崎 | Q4: 10/30現在有休残３日、11/29付与12日、合計15日新開工場長へline済み | R4: 45971 | S4: 0.52361111 | T4: 尾崎 | U4: /appsheet/rireki_photo/3.対応画像２ー１.231248.jpg | V4: /appsheet/rireki_photo/3.対応画像２－２.231248.jpg | W4: 3/13結婚のため、一時帰国。5/10頃帰国し在留カード更新手続きを行うと話す。 | AA4: /appsheet/rireki_photo/3.対応画像３ー１.060848.jpg | AB4: /appsheet/rireki_photo/3.対応画像３－２.060848.jpg | AD4: 46092 | AE4: 0.37976852 | AF4: 尾崎 | AG4: /appsheet/rireki_photo/3.対応画像４ー１.000907.jpg | AI4: 3/12松山発17:40に変更。インドネシアへはノヴィと一緒
A5: 4 | B5: 45960 | C5: 0.41168981 | D5: 尾崎 | E5: 07013685 | G5: 退職 | H5: 完了 | K5: ザーラより、LINEにて、12/20を最終出勤日として翌1/5の飛行機で大学に行くため帰国したい申し出。新開工場長へ電話にて報告 | L5: 45960 | M5: 0.45572917 | N5: 尾崎 | Q5: 10/30現在有休残４日。付与日は4/29のため、４日で新開工場長へline済 | R5: 45971 | S5: 0.54861111 | T5: 尾崎 | U5: /appsheet/rireki_photo/4.対応画像２ー１.041443.jpg | W5: 本人より、12/20退職、12/末現金給与、1/7松山空港発(1/7退寮)、1/10東京発でチケットとった。チケット送付依頼し、そのスケジュールにて進めると伝える。1/10羽田空港11:45発 | AP5: 最終出勤12/18 12/19と12/20は有給使用
A6: 5 | B6: 45960 | C6: 0.42792824 | D6: 尾崎 | E6: 07001616 | F6: アトム705 | G6: 購入 | H6: 完了 | I6: /appsheet/rireki_photo/5.登録画像１－１.012008.jpg | J6: /appsheet/rireki_photo/5.登録画像１－２.012009.jpg | K6: ヒエンの妹が入社するので、エアコン設置依頼 | L6: 45960 | M6: 0.44371528 | N6: 尾崎 | Q6: 竹内空調さんへ11/18までに設置依頼 | R6: 45966 | S6: 0.44652778 | T6: 尾崎 | U6: /appsheet/rireki_photo/5.対応画像２ー１.043834.jpg | W6: 竹内空調にて設置済み 三菱エアコン 77,000税別 月末締め翌月OK
A7: 6 | B7: 45961 | C7: 0.3125 | D7: 尾崎 | F7: コーポ津吉1-6 | G7: 修理 | H7: 完了 | K7: コーポ津吉1-6で３日間Wifiが使えない状態の申し出。 | L7: 45962 | M7: 0.47222222 | N7: 尾崎 | Q7: 電源及び配線再起動により稼働、マデ休みにより
A8: 7 | B8: 45961 | C8: 0.69521991 | D8: 尾崎 | E8: 07018606 | G8: 問合せ | H8: 完了 | I8: /appsheet/rireki_photo/7.登録画像１－１.074924.jpg | J8: /appsheet/rireki_photo/7.登録画像１－２.074924.jpg | K8: 新開工場長より、インドネシア時より、脊髄がまがる病気で重たいもの等をもつ仕事を変更してほしいとの申し出あり。入国前の健康診断でも問題がないため入国ができ、入国後の健康診断でも該当ないため、本人と面談を行う | L8: 45962 | M8: 0.60416667 | N8: 尾崎 | Q8: デフィとヤニと４人で牛渕２号館ではなし。病院には行ってない。とりあえず、できるところまでやってみて、ダメになる前に上長へ。新開工場長へ報告済み
A9: 8 | B9: 45963 | C9: 0.52013889 | D9: 尾崎 | E9: 07013638 | G9: 妊娠 | H9: 対応中 | K9: エカより、ニマが妊娠13週との連絡あり。今後について、相談すると伝える。 | L9: 45965 | M9: 0.35666667 | N9: 尾崎 | Q9: 新開工場長へline連絡 | R9: 45966 | S9: 0.52430556 | T9: 尾崎 | W9: エカと３人で津吉社長室にて話す。出産予定5/5、つばきウイメンズで出産予定、日本にて産みたい。エカも特定２号受けたい。入社が2025/6/17、転職のため、特定１号の期限が2027/3までのため、入官へ確認 | X9: 46091 | Y9: 0.53799769 | Z9: 尾崎 | AA9: /appsheet/rireki_photo/8.対応画像３ー１.235743.jpg | AC9: 出産を県立中央病院へ変更した。予定通り3/25より産休予定
A10: 9 | B10: 45965 | C10: 0.54489583 | D10: 池内 | E10: 07011609 | G10: 問合せ | H10: 完了 | K10: 11/4ヅエンから尾崎さんへ就労証明書発行依頼あり。→恒岡さんへ記入依頼済。出来上がり次第ヅエンへ届ける。 | L10: 45966 | M10: 0.45833333 | N10: 尾崎 | Q10: 本人へ就労証明書と年末調整の書類を渡す。年末調整は後日取りに来ると伝える。 | R10: 45972 | S10: 0.3849537 | T10: 尾崎 | W10: 年末調整及び送金明細書回収する
A11: 10 | B11: 45967 | C11: 0.4025463 | D11: 池内 | E11: 07001423 | F11: アトム401 | G11: 病院 | H11: 完了 | K11: 11/6朴さんより宮内工場長へ連絡あり。ディンが4か月ほど生理が来ていないらしく、11/18に中四国が婦人科へ連れていくとのこと。 | N11: 池内 | Q11: 一応、生理再開したとのことで病院は行かないことになった。
A12: 11 | B12: 45968 | C12: 0.2875 | D12: 尾崎 | E12: 07013682 | G12: 退職 | H12: 完了 | I12: /appsheet/rireki_photo/11.登録画像１－１.215912.jpg | K12: 新開工場長より、２/２０退職、１０日後退寮の申し出あり、確認依頼。 | L12: 45971 | M12: 0.54861111 | N12: 尾崎 | Q12: 2/20退職してインドネシアに帰国する。2/末給料、3/1に松山発の予定。
A13: 12 | B13: 45968 | C13: 0.33855324 | D13: 尾崎 | E13: 07001618 | F13: アトム404 | G13: 病院 | H13: 完了 | I13: /appsheet/rireki_photo/12.登録画像１－１.231036.jpg | K13: 宮内工場長に、皮膚に発疹みたいなものがあり、病院に行きたい申し出あり。11/7、９時に連れていく旨連絡。 | L13: 45968 | N13: 池内 | Q13: 二宮皮ふ科受診。全身にかゆみと発疹あり。蕁麻疹と診断。２日前くらいから出ているので、食べ物などのアレルギーではなさそう。免疫低下やストレス？薬飲んで様子見る。
A14: 13 | B14: 45968 | C14: 0.3666088 | D14: 尾崎 | E14: 07012622 | G14: 病院 | H14: 完了 | K14: 11/17月曜日、子宮筋腫の手術 | L14: 45981 | M14: 0.48888889 | N14: 尾崎 | Q14: 恒岡さんより、デルタ四国の通訳よりTELあり、手術跡が大きく、当初11/30までやすみだったが、12/20ごろまでには出勤すると連絡あり。後日、12/1～の休暇届作成すること | R14: 45987 | S14: 0.62157407 | T14: 尾崎 | W14: 本人と面談。12/3水曜日が通院日。12/20まで傷口が大きいため休暇申出。12/3病院受診時に診断書をもらうとのこと
A15: 14 | B15: 45968 | C15: 0.52083333 | D15: 尾崎 | E15: 07018631 | G15: 紛失 | H15: 完了 | K15: 在留カードが、銀行口座作成してから紛失。探したが見つからず。とりあえず、コピーを渡す。 | L15: 45969 | N15: 池内 | Q15: 11/6在留カード紛失の申し出。11/8に南署にて遺失物届を出した。受理番号1669。11/10に入管へ在留カード再発行申請をする予定。 | R15: 45971 | S15: 0.51388889 | T15: 尾崎 | W15: 入官にて在留カード再発行を行い、昼、食堂にて渡す。
A16: 15 | B16: 45968 | C16: 0.5625 | D16: 尾崎 | E16: 07011606 | G16: 一時帰国 | H16: 完了 | K16: ２号試験終了後、２月初めから、２ヶ月一時帰国したい申し出あり。水沼さん了承。 | L16: 46016 | M16: 0.56597222 | N16: 尾崎 | O16: /appsheet/rireki_photo/15.対応画像１ー２.073801.jpg | Q16: 1/24～３/24まで一時帰国。広島空港発着
A17: 16 | B17: 45971 | C17: 0.43055556 | D17: 尾崎 | E17: 07013679 | G17: 病院 | H17: 完了 | K17: 新開工場長より、手が痛いので病院へ連れていってほしいとの依頼あり。以前、尾崎に話してたとのこと。10/4に日曜日に診察できる整形外科の案内があり、南松山病院を案内。その当時、ハクと一緒に行くと行っていたが、実際に診察したかどうかは不明。本日お昼に確認する。 | L17: 45971 | M17: 0.52708333 | N17: 尾崎 | Q17: 手首は痛いが、木曜日か金曜日でOK。新開工場長へ伝え、時間が分かったら連絡依頼。10/4は整形外科の先生がいないため診察しなかった。金澤整形でもOK | R17: 45974 | T17: 池内 | W17: 11.13金澤受診。重いものや手首の曲げで負担かかっている。レントゲンにて、左手首、少し炎症してる。電気治療を何度か行いリハビリで様子見る。次回は11.29リハビリ。イーサンは次回より１人で受診
A18: 17 | B18: 45971 | C18: 0.48396991 | D18: 池内 | E18: 07013665 | F18: ビレッジ2-502 | G18: 病院 | H18: 完了 | K18: 同部屋のアルバシタから、アイナの体調不良とLINEあり。数日前から声が出なくなっていた。近くのよしおか内科を案内。 | L18: 45971 | M18: 0.52916667 | N18: 尾崎 | Q18: アルバシタと話す。イナは今日11:30～仕事で熱はなく声が出ない様子。明日、昼からなので、午前中、病院へ行くなら８時までにLINE依頼 | R18: 45972 | T18: 池内 | U18: /appsheet/rireki_photo/17.対応画像２ー１.052518.jpg | W18: 11/11 よしおか内科受診。熱はないため検査なし。鼻水・咳・声枯れの症状で薬飲んで様子見。仕事は通常通り勤務する。
A19: 18 | B19: 45971 | C19: 0.57321759 | D19: 尾崎 | E19: 07011602 | G19: 退職 | H19: 完了 | K19: 2026/2月に退職して帰国したい申し出。新開工場長へ連絡済み。帰りの飛行機代を確認依頼。 | L19: 45988 | M19: 0.52430556 | N19: 尾崎 | O19: 履歴_Images/18.対応画像１ー２.025523.jpg | P19: /appsheet/rireki_photo/18.対応画像１－２.025523.jpg | Q19: 2/14広島空港13:00発チケット、交通手段確認 | R19: 46010 | S19: 0.52680556 | T19: 尾崎 | V19: /appsheet/rireki_photo/18.対応画像２－２.065708.jpg | W19: 広島空港までは自分で行くとのこと | X19: 46062 | Y19: 0.66180556 | Z19: 尾崎 | AA19: /appsheet/rireki_photo/18.対応画像３ー１.065516.jpg | AB19: /appsheet/rireki_photo/18.対応画像３－２.065516.jpg | AC19: 銀行及び転出届、広島空港２つ荷物をヤマト運輸持ち込み。保険証回収済み。家の鍵と自転車鍵はハンヘ土曜日に渡すとのこと。
A20: 19 | B20: 45972 | C20: 0.53215278 | D20: 尾崎 | E20: 07012626 | G20: 退職 | H20: 完了 | I20: /appsheet/rireki_photo/19.登録画像１－１.082907.jpg | J20: /appsheet/rireki_photo/19.登録画像１－２.082907.jpg | K20: 退寮日が変更になった。11/20退職、11/21退寮、11/21の15時頃の飛行機。11/21の9時部屋の立ち会いだが、事前に１８日～２０日までに部屋確認すると伝える | L20: 45975 | M20: 0.43541667 | N20: 尾崎 | O20: 履歴_Images/19.対応画像１ー２.082907.jpg | P20: /appsheet/rireki_photo/19.対応画像１－２.082910.jpg | Q20: 日曜日に掃除とゴミを捨てるよう指示。最終11/21の１０時訪問予定 | R20: 45982 | S20: 0.41666667 | T20: 尾崎 | W20: 退去確認。部屋の鍵、自転車の鍵、保険証預り終了。デルタ四国立会
A21: 20 | B21: 45972 | C21: 0.56527778 | D21: 尾崎 | E21: 07012622 | G21: 問合せ | H21: 完了 | K21: ビレッジ中野さんから、松山南警察地域課高山さん958-0110より自転車が置かれており撤去依頼があったと連絡あり。 | L21: 45972 | M21: 0.57054398 | N21: 尾崎 | Q21: 昼休憩にて本人がおり、自転車撤去に向かう。朝、出勤時にアンディ二が自転車でこけてククが自転車で会社に連れて行った。アンディ二の自転車をチャンが乗って行って、チャンの自転車を日野車体の車庫に置いたため、日野車体より警察に連絡が入る。仕事終わりに取りに行く予定だった。 | R21: 45972 | S21: 0.58333333 | T21: 尾崎 | W21: チャン同席の上、日野車体に訪問し、お詫びし自転車を回収する。結構お怒りモードだったが、ご迷惑おかけしたことお詫びし了承をえる。 | AP21: 大澤専務に報告後、新開工場長へ栗ご飯の素持参予定
A22: 21 | B22: 45973 | C22: 0.32853009 | D22: 尾崎 | E22: 07013685 | G22: 病院 | H22: 完了 | I22: /appsheet/rireki_photo/21.登録画像１－１.024607.jpg | J22: /appsheet/rireki_photo/21.登録画像１－２.024607.jpg | K22: 昨日から背中が痛いので病院へ行きたいとの申し出あり。 | L22: 45974 | N22: 池内 | Q22: 右脇腹あたりが痛む。息するのも痛みがあるため、金澤受診。レントゲンをとり、症状から骨にヒビが入ってる可能性があるとのこと。固定バンドをつけて生活するように言われた。11.20に金澤を受診するよう言われた。１人では不安なので付き添って欲しいとのこと。仕事については、本人の無理のない範囲で行うよう伝えた | R22: 45981 | T22: 池内 | W22: 呼吸時の痛みは治まったが、まだ起き上がるとき辛い。固定バンド外してたので、お風呂以外はバントするよう伝えた。12/4受診予定 | X22: 45999 | Z22: 池内 | AC22: 12/4にて、通院終了
A23: 22 | B23: 45973 | C23: 0.53592593 | D23: 尾崎 | E23: 07012625 | G23: 妊娠 | H23: 完了 | K23: 昨日、病院へ行って妊娠４週ぐらい。まだ小さいため、安定したら再度話す。新開工場長へは連絡済み | L23: 45978 | M23: 0.52777778 | N23: 尾崎 | Q23: ブイより、流産したと報告あり。タオは本日休み。
A24: 23 | B24: 45975 | C24: 0.46601852 | D24: 池内 | E24: 07001423 | F24: アトム401 | G24: 病院 | H24: 完了 | K24: 藤原さんより、ディンが体調不良なのか、仕事に来てないので部屋に見に行って欲しいとのことで渡部さんに見に行ってもらった。生理痛がひどく寝込んでいた。15日の昼から仕事に行くとのこと。18日には中四国と一緒に婦人科へ受診することになっている→病院行かなくていいとのこと。 | L24: 45975 | N24: 渡部
A25: 24 | B25: 45975 | C25: 0.95833333 | D25: 尾崎 | E25: 07018624 | F25: 牛渕１ | G25: 病院 | H25: 完了 | I25: /appsheet/rireki_photo/24.登録画像１－１.013658.jpg | K25: エヴィより、手が腫れて病院へ行きたいとの申し出あり。11/15土曜日8:45迎え行くと伝える | L25: 45976 | M25: 0.375 | N25: 尾崎 | O25: 履歴_Images/24.対応画像１ー２.013658.jpg | P25: /appsheet/rireki_photo/24.対応画像１－２.013658.jpg | Q25: 金澤整形に受診、新開工場長と相談し、手の固定されてるので11/16休み、11/17病院へ行き、手の固定がどうなるかで勤務するか判断。11/17、11/20に病院へ行くと伝える。11/17金澤整形受診、痛みもまだあり固定器具もはずせないため、11/20受診まで休み、新開工場長へ連絡済み | R25: 45981 | T25: 池内 | U25: /appsheet/rireki_photo/24.対応画像２ー１.005843.jpg | W25: まだ内出血で腫れている。指を曲げるような仕事は控えるよう言われた。本人が早く仕事復帰したいというので、新開さんへ事情を伝えた上で11/20昼から勤務してみるとのこと。次回11/27受診予定。 | X25: 45995 | Z25: 池内 | AC25: 12/4受診。また来週も来るよう言われたが、本人はもう行かなくても大丈夫と言ってるので、今回で通院終了。 | AP25: 11/27 経過良好だが、まだ少し痛み残っているため12/4に受診予定がある。オクトリヴィアも4日に受診なので二人で行くよう伝えた。12/11再診。痛みはないが右手握れない。
A26: 25 | B26: 45975 | C26: 0.54166667 | D26: 渡部 | E26: 07001618 | F26: アトム404 | G26: 問合せ | H26: 完了 | K26: 宮内工場長より、アトムマンションに自転車を停めていたところ、紛失したとのこと。本人に詳細確認予定。 | L26: 45976 | M26: 0.5 | N26: 渡部 | Q26: ロンに詳細を確認したところ、11/11(火)の15時頃に買い物に行こうとしたところ無くなっていた。鍵はかけておいていた。代替自転車が必要とのことで、準備が出来し伝える。 | R26: 45976 | S26: 0.5 | T26: 池内 | U26: /appsheet/rireki_photo/25.対応画像２ー１.054120.jpg | W26: 自転車6656（B-0246656）が準備できたので、ロンに鍵を渡した。
A27: 26 | B27: 45976 | C27: 0.55780093 | D27: 渡部 | E27: 07012622 | G27: 病院 | H27: 完了 | K27: 子宮筋腫の手術のため、デルタより病院からの連帯保証人に雇用主様にて対応をお願いしたいとのメールあり。専務に確認したところ弊社で対応する旨了承済み。傷病手当で進めるようにとのこと。 | L27: 45967 | M27: 0.83333333 | N27: 渡部 | R27: 45975 | S27: 0.41666667 | T27: 渡部 | W27: 病院からの書類をデルタへ渡した。休暇届けをデルタの松岡さんに代筆で記入してもらう。傷病手当の書類を2セット渡し済み。11/20締めで1回目の申請をすると伝えた。 | X27: 46013 | Y27: 0.4375 | Z27: 渡部 | AC27: デルタ 松岡さんより、傷病手当の書類が揃い次第、持って来られる予定。 | AP27: 書類回収により申請終了
A28: 27 | B28: 45976 | C28: 0.47916667 | D28: 尾崎 | E28: 07018627 | F28: 中野２ | G28: 修理 | H28: 完了 | K28: 自転車が何かおかしい。中野２に置いている | L28: 45976 | M28: 0.57361111 | N28: 尾崎 | O28: 履歴_Images/27.対応画像１ー２.044644.jpg | Q28: 後輪にネジが刺さっていたため、抜いて対応終了
A29: 28 | B29: 45978 | C29: 0.32796296 | D29: 尾崎 | E29: 07013631 | F29: ビレッジ3-507 | G29: 病院 | H29: 完了 | K29: ナウファルより腰が痛いので病院へ連れていってほしいと連絡あり | L29: 45978 | M29: 0.375 | N29: 尾崎 | Q29: 金澤整形受診。ぎっくり腰のため、次回11/20、痛みがまだあるようなら、11/27受診依頼。次回は自転車で行くよう指示。 | R29: 45988 | T29: 池内 | W29: 痛みほぼ治った。今ある薬飲み切ってもう病院行かなくていいとのこと。
A30: 29 | B30: 45978 | C30: 0.34761574 | D30: 池内 | E30: 07018616 | F30: 牛渕１ | G30: 病院 | H30: 完了 | K30: 入社時の健康診断で貧血で要治療判定。専務より、貧血で倒れるといけないので病院を受診するよう言われた。有給がないため、土曜日に受診できる中野クリニックに行く予定。11/29午前中受診予定 | L30: 45990 | M30: 0.37506944 | N30: 渡部 | Q30: 中野クリニック受診。鉄欠乏性貧血と診断され、1カ月薬を服用し、飲みきったら再度受診し採血の予定。
A31: 30 | B31: 45976 | C31: 0.90277778 | D31: 尾崎 | E31: 07013669 | F31: ビレッジ3-508 | G31: 修理 | H31: 完了 | I31: /appsheet/rireki_photo/30.登録画像１－１.234126.jpg | J31: /appsheet/rireki_photo/30.登録画像１－２.001414.jpg | K31: 自転車がパンクしたと申し出あり。月曜日に対応する。カギが必要と伝える。 | L31: 45978 | M31: 0.625 | N31: 尾崎 | O31: 履歴_Images/30.対応画像１ー２.065249.jpg | P31: /appsheet/rireki_photo/30.対応画像１－２.065248.jpg | Q31: タイヤ交換、4,000円、鍵を前かごにいれる
A32: 31 | B32: 45979 | C32: 0.33490741 | D32: 池内 | E32: 07018621 | F32: 牛渕１ | G32: 修理 | H32: 完了 | K32: 11/17の夜からガスが使えなくなったとの連絡あり。尾崎さんに見に行ってもらう。 | L32: 45979 | M32: 0.39583333 | N32: 尾崎 | O32: 履歴_Images/31.対応画像１ー２.023432.jpg | P32: /appsheet/rireki_photo/31.対応画像１－２.023432.jpg | Q32: トーカイガス089-932-3351に来てもらい、復旧。ガス欠だった。
A33: 32 | B33: 45980 | C33: 0.51388889 | D33: 尾崎 | E33: 07011612 | F33: コーポ津吉1-2 | G33: 病院 | H33: 完了 | I33: /appsheet/rireki_photo/32.登録画像１－１.215921.jpg | K33: 健診で大腸がんの健診を受けるよう話す。来週夜勤のため受診可能。 | L33: 45981 | M33: 0.50979167 | N33: 尾崎 | O33: 履歴_Images/32.対応画像１ー２.074922.jpg | P33: /appsheet/rireki_photo/32.対応画像１－２.074922.jpg | Q33: ■ 診察予約 【診察日時】2025年11月25日 10:30 【医療機関】眞柴消化器内科クリニック（TEL: 0899681202) 11/28(金)12：00～16:00大腸内視鏡検査 28日は仕事休むこと新開さんへ連絡済 | R33: 45989 | S33: 0.68055556 | T33: 池内 | W33: 検査問題なく終了。異常もなく、結果は問題なし。
A34: 33 | B34: 45981 | C34: 0.50809028 | D34: 尾崎 | E34: 07001605 | G34: 一時帰国 | H34: 完了 | K34: 宮内工場長より2025/12/25～2/3まで一時帰国の申出あり。チケットは中温で取得の要請あり。 | L34: 45982 | M34: 0.61393519 | N34: 尾崎 | O34: 履歴_Images/33.対応画像１ー２.030953.jpg | P34: /appsheet/rireki_photo/33.対応画像１－２.030953.jpg | Q34: 関西国際空港 12/25 10:00発 13:30着 ハノイ 2/2 01:05発 06:55着 往復115,800-にてチケット手配
A35: 34 | B35: 45985 | C35: 0.405 | D35: 池内 | E35: 07018630 | F35: 中野２ | G35: 病院 | H35: 完了 | K35: 11/23に歯が痛く熱もあり病院に行きたいとLINEあり。休日2連休で病院も休診で職員も休日のため、25日まで様子見るとのこと。 | L35: 45985 | M35: 0.42083333 | N35: 尾崎 | O35: 履歴_Images/34.対応画像１ー２.010745.jpg | P35: /appsheet/rireki_photo/34.対応画像１－２.022749.jpg | Q35: 11/25、9:30～グリーン歯科予約 11/25右奥歯下が腫れてて抜くしかない。３日分の化膿止めと熱覚ましをもらい、12/2に抜く予定。病院の先生より、疲れと化膿及び熱があるため木曜日まで休み。木曜日に症状連絡依頼→11/27少し腫れているが、痛み治まってきたので11/28から出勤。 | R35: 45993 | T35: 池内 | U35: /appsheet/rireki_photo/34.対応画像２ー１.022749.jpg | W35: 12/2抜歯した。12/9 9：30に消毒の為、再受診
A36: 35 | B36: 45986 | C36: 0.49087963 | D36: 尾崎 | E36: 07013633 | G36: 結婚 | H36: 対応中 | K36: ナナより、デウィマシトと来年結婚する。2026/7/18～9/4まで帰国結婚、中温で２人で住居したい申出。日程については、新開工場長と相談済。 | L36: 46058 | M36: 0.51597222 | N36: 尾崎 | Q36: ナナとLINE交換しやり取りすると伝える | R36: 46065 | S36: 0.53194444 | T36: 尾崎 | U36: /appsheet/rireki_photo/35.対応画像２ー１.224711.jpg | V36: /appsheet/rireki_photo/35.対応画像２－２.224710.jpg | W36: ナナより、チケットもらう
A37: 36 | B37: 45987 | C37: 0.60922454 | D37: 尾崎 | F37: 牛渕２ | G37: 問合せ | H37: 完了 | I37: /appsheet/rireki_photo/36.登録画像１－１.053858.jpg | K37: ６、２５、３６、８、１、１２、１５、１４ | L37: 45987 | M37: 0.62375 | N37: 尾崎 | Q37: ６の自転車を中野１へ移動
A38: 37 | B38: 45987 | C38: 0.6172338 | D38: 尾崎 | F38: 牛渕１ | G38: 修理 | H38: 完了 | I38: /appsheet/rireki_photo/37.登録画像１－１.055108.jpg | K38: 電気が弱い | L38: 45987 | M38: 0.61736111 | N38: 尾崎 | O38: 履歴_Images/37.対応画像１ー２.055108.jpg | Q38: 電球が切れているため、電球交換
A39: 38 | B39: 45988 | C39: 0.52805556 | D39: 池内 | E39: 07013653 | F39: 牛渕２ | G39: 病院 | H39: 完了 | K39: 口の周りが荒れて痛みがあり皮膚科に行きたいと申し出。１人で行くのは不安なので着いてきてほしいとのこと。11/29 9:00八木皮膚科受診予定 | L39: 45990 | N39: 池内 | Q39: 歯磨き粉や、リップクリームが合わないのかも？ワセリン100パーのものを使うこと、口の周りを拭きすぎないことを指導された。塗り薬を1～2週間使って治らなければ再受診。
A40: 39 | B40: 45988 | C40: 0.84733796 | D40: 池内 | E40: 07013649 | G40: 退職 | H40: 完了 | I40: /appsheet/rireki_photo/39.登録画像１－１.112134.jpg | K40: デラよりLINEで退職したい申し出あり。いつ頃退職して帰国したいのかヒアリングする。有給残12日（12月付与）と４時間 | L40: 45990 | N40: 池内 | O40: /appsheet/rireki_photo/39.対応画像１ー２.013036.jpg | Q40: デラと話し、退職希望日は1/20だが、1月が厳しいなら2/20でも構わない。とりあえず体調がよくないので帰国したいとのこと。新開さんへLINE済。→新開さんより2/20退職で。とのこと。デラにLINE済
...

Sheet 集計
N1: 通訳 | O1: ベトナム | P1: NGUYEN VAN HOI | Q1: グエン バン ホイ | R1: 070-1057-6789 | S1: 埼玉県さいたま市桜区西堀2-10-36-302号
A2: 区分 | B2: 区分人数 | C2: 男女区分 | D2: 男女人数 | E2: 国籍 | F2: 国籍人数 | G2: 実習生 | H2: 特定技能 | O2: インドネシア | P2: AO HENDARSO | Q2: アオ ヘンダルソ | R2: 090-9822-1984
A3: 本社 | B3: =COUNTIFS(管理表!C:C,A3,管理表!AH:AH,"<>退職") -> 35 | C3: 男 | D3: =COUNTIFS(管理表!C:C,A3,管理表!AH:AH,"<>退職",管理表!J:J,C3) -> 11 | E3: ベトナム | F3: =COUNTIFS(管理表!C:C,A3,管理表!AH:AH,"<>退職",管理表!J:J,C3,管理表!D:D,E3) -> 11 | G3: =COUNTIFS(管理表!C:C,A3,管理表!AH:AH,"<>退職",管理表!J:J,C3,管理表!D:D,E3,管理表!Q:Q,"*実習*") -> 4 | H3: =COUNTIFS(管理表!C:C,A3,管理表!AH:AH,"<>退職",管理表!J:J,C3,管理表!D:D,E3,管理表!Q:Q,"*特定*") -> 7
E4: インドネシア | F4: =COUNTIFS(管理表!C:C,A3,管理表!AH:AH,"<>退職",管理表!J:J,C3,管理表!D:D,E4) -> 0 | G4: =COUNTIFS(管理表!C:C,A3,管理表!AH:AH,"<>退職",管理表!J:J,C3,管理表!D:D,E4,管理表!Q:Q,"*実習*") -> 0 | H4: =COUNTIFS(管理表!C:C,A3,管理表!AH:AH,"<>退職",管理表!J:J,C3,管理表!D:D,E4,管理表!Q:Q,"*特定*") -> 0
C5: 女 | D5: =COUNTIFS(管理表!C:C,A3,管理表!AH:AH,"<>退職",管理表!J:J,C5) -> 24 | E5: ベトナム | F5: =COUNTIFS(管理表!C:C,A3,管理表!AH:AH,"<>退職",管理表!J:J,C5,管理表!D:D,E5) -> 24 | G5: =COUNTIFS(管理表!C:C,A3,管理表!AH:AH,"<>退職",管理表!J:J,C5,管理表!D:D,E5,管理表!Q:Q,"*実習*") -> 13 | H5: =COUNTIFS(管理表!C:C,A3,管理表!AH:AH,"<>退職",管理表!J:J,C5,管理表!D:D,E5,管理表!Q:Q,"*特定*") -> 11
E6: インドネシア | F6: =COUNTIFS(管理表!C:C,A3,管理表!AH:AH,"<>退職",管理表!J:J,C5,管理表!D:D,E6) -> 0 | G6: =COUNTIFS(管理表!C:C,A3,管理表!AH:AH,"<>退職",管理表!J:J,C5,管理表!D:D,E6,管理表!Q:Q,"*実習*") -> 0 | H6: =COUNTIFS(管理表!C:C,A3,管理表!AH:AH,"<>退職",管理表!J:J,C5,管理表!D:D,E6,管理表!Q:Q,"*特定*") -> 0
A7: 協同本社 | B7: =COUNTIFS(管理表!C:C,A7,管理表!AH:AH,"<>退職") -> 4 | C7: 男 | D7: =COUNTIFS(管理表!C:C,A7,管理表!AH:AH,"<>退職",管理表!J:J,C7) -> 2 | E7: ベトナム | F7: =COUNTIFS(管理表!C:C,A7,管理表!AH:AH,"<>退職",管理表!J:J,C7,管理表!D:D,E7) -> 2 | G7: =COUNTIFS(管理表!C:C,A7,管理表!AH:AH,"<>退職",管理表!J:J,C7,管理表!D:D,E7,管理表!Q:Q,"*実習*") -> 2 | H7: =COUNTIFS(管理表!C:C,A7,管理表!AH:AH,"<>退職",管理表!J:J,C7,管理表!D:D,E7,管理表!Q:Q,"*特定*") -> 0
E8: インドネシア | F8: =COUNTIFS(管理表!C:C,A7,管理表!AH:AH,"<>退職",管理表!J:J,C7,管理表!D:D,E8) -> 0 | G8: =COUNTIFS(管理表!C:C,A7,管理表!AH:AH,"<>退職",管理表!J:J,C7,管理表!D:D,E8,管理表!Q:Q,"*実習*") -> 0 | H8: =COUNTIFS(管理表!C:C,A7,管理表!AH:AH,"<>退職",管理表!J:J,C7,管理表!D:D,E8,管理表!Q:Q,"*特定*") -> 0
C9: 女 | D9: =COUNTIFS(管理表!C:C,A7,管理表!AH:AH,"<>退職",管理表!J:J,C9) -> 2 | E9: ベトナム | F9: =COUNTIFS(管理表!C:C,A7,管理表!AH:AH,"<>退職",管理表!J:J,C9,管理表!D:D,E9) -> 2 | G9: =COUNTIFS(管理表!C:C,A7,管理表!AH:AH,"<>退職",管理表!J:J,C9,管理表!D:D,E9,管理表!Q:Q,"*実習*") -> 2 | H9: =COUNTIFS(管理表!C:C,A7,管理表!AH:AH,"<>退職",管理表!J:J,C9,管理表!D:D,E9,管理表!Q:Q,"*特定*") -> 0
E10: インドネシア | F10: =COUNTIFS(管理表!C:C,A7,管理表!AH:AH,"<>退職",管理表!J:J,C9,管理表!D:D,E10) -> 0 | G10: =COUNTIFS(管理表!C:C,A7,管理表!AH:AH,"<>退職",管理表!J:J,C9,管理表!D:D,E10,管理表!Q:Q,"*実習*") -> 0 | H10: =COUNTIFS(管理表!C:C,A7,管理表!AH:AH,"<>退職",管理表!J:J,C9,管理表!D:D,E10,管理表!Q:Q,"*特定*") -> 0
A11: 本社小計 | B11: =B3+B7 -> 39 | C11: 男 | D11: =D3+D7 -> 13 | E11: ベトナム | F11: =F3+F7 -> 13 | G11: =G3+G7 -> 6 | H11: =H3+H7 -> 7
E12: インドネシア | F12: =F4+F8 -> 0 | G12: =G4+G8 -> 0 | H12: =H4+H8 -> 0
C13: 女 | D13: =D5+D9 -> 26 | E13: ベトナム | F13: =F5+F9 -> 26 | G13: =G5+G9 -> 15 | H13: =H5+H9 -> 11
E14: インドネシア | F14: =F6+F10 -> 0 | G14: =G6+G10 -> 0 | H14: =H6+H10 -> 0
A15: 津吉 | B15: =COUNTIFS(管理表!C:C,A15,管理表!AH:AH,"<>退職") -> 109 | C15: 男 | D15: =COUNTIFS(管理表!C:C,A15,管理表!AH:AH,"<>退職",管理表!J:J,C15) -> 33 | E15: ベトナム | F15: =COUNTIFS(管理表!C:C,A15,管理表!AH:AH,"<>退職",管理表!J:J,C15,管理表!D:D,E15) -> 2 | G15: =COUNTIFS(管理表!C:C,A15,管理表!AH:AH,"<>退職",管理表!J:J,C15,管理表!D:D,E15,管理表!Q:Q,"*実習*") -> 0 | H15: =COUNTIFS(管理表!C:C,A15,管理表!AH:AH,"<>退職",管理表!J:J,C15,管理表!D:D,E15,管理表!Q:Q,"*特定*") -> 2
E16: インドネシア | F16: =COUNTIFS(管理表!C:C,A15,管理表!AH:AH,"<>退職",管理表!J:J,C15,管理表!D:D,E16) -> 31 | G16: =COUNTIFS(管理表!C:C,A15,管理表!AH:AH,"<>退職",管理表!J:J,C15,管理表!D:D,E16,管理表!Q:Q,"*実習*") -> 0 | H16: =COUNTIFS(管理表!C:C,A15,管理表!AH:AH,"<>退職",管理表!J:J,C15,管理表!D:D,E16,管理表!Q:Q,"*特定*") -> 31
C17: 女 | D17: =COUNTIFS(管理表!C:C,A15,管理表!AH:AH,"<>退職",管理表!J:J,C17) -> 76 | E17: ベトナム | F17: =COUNTIFS(管理表!C1:C1024,A15,管理表!AH:AH,"<>退職",管理表!J:J,C17,管理表!D:D,E17) -> #VALUE! | G17: =COUNTIFS(管理表!C:C,A15,管理表!AH:AH,"<>退職",管理表!J:J,C17,管理表!D:D,E17,管理表!Q:Q,"*実習*") -> 0 | H17: =COUNTIFS(管理表!C:C,A15,管理表!AH:AH,"<>退職",管理表!J:J,C17,管理表!D:D,E17,管理表!Q:Q,"*特定*") -> 8
E18: インドネシア | F18: =COUNTIFS(管理表!C:C,A15,管理表!AH:AH,"<>退職",管理表!J:J,C17,管理表!D:D,E18) -> 68 | G18: =COUNTIFS(管理表!C:C,A15,管理表!AH:AH,"<>退職",管理表!J:J,C17,管理表!D:D,E18,管理表!Q:Q,"*実習*") -> 0 | H18: =COUNTIFS(管理表!C:C,A15,管理表!AH:AH,"<>退職",管理表!J:J,C17,管理表!D:D,E18,管理表!Q:Q,"*特定*") -> 68
A19: 合計 | B19: =B3+B7+B15 -> 148 | C19: 男 | D19: =D3+D7+D15 -> 46 | E19: ベトナム | F19: =F3+F7+F15 -> 15 | G19: =G3+G7+G15 -> 6 | H19: =H3+H7+H15 -> 9 | N19: 5211
E20: インドネシア | F20: =F4+F8+F16 -> 31 | G20: =G4+G8+G16 -> 0 | H20: =H4+H8+H16 -> 31
C21: 女 | D21: =D5+D9+D17 -> 102 | E21: ベトナム | F21: =F5+F9+F17 -> #VALUE! | G21: =G5+G9+G17 -> 15 | H21: =H5+H9+H17 -> 19 | K21: 松山市末広町 | L21: ７９０－００２３
E22: インドネシア | F22: =F6+F10+F18 -> 68 | G22: =G6+G10+G18 -> 0 | H22: =H6+H10+H18 -> 68 | K22: 松山市中野町 | L22: ７９１－１１２１
A24: 区分 | B24: 区分人数 | C24: 男女区分 | D24: 男女人数 | E24: 国籍 | F24: 国籍人数 | G24: 実習生 | H24: 特定技能 | I24: 本社 | J24: 協同本社 | K24: 津吉
A25: 関東食肉 | B25: =COUNTIFS(管理表!N:N,A25,管理表!AH:AH,"<>退職") -> 9 | C25: 男 | D25: =COUNTIFS(管理表!N:N,A25,管理表!AH:AH,"<>退職",管理表!J:J,C25) -> 2 | E25: ベトナム | F25: =COUNTIFS(管理表!N:N,A25,管理表!AH:AH,"<>退職",管理表!J:J,C25,管理表!D:D,E25) -> 2 | G25: =COUNTIFS(管理表!N:N,A25,管理表!AH:AH,"<>退職",管理表!J:J,C25,管理表!D:D,E25,管理表!Q:Q,"*実習*") -> 2 | H25: =COUNTIFS(管理表!N:N,A25,管理表!AH:AH,"<>退職",管理表!J:J,C25,管理表!D:D,E25,管理表!Q:Q,"*特定*") -> 0 | I25: =COUNTIFS(管理表!N:N,A25,管理表!AH:AH,"<>退職",管理表!J:J,C25,管理表!D:D,E25,管理表!C:C,"本社") -> 2 | J25: =COUNTIFS(管理表!N:N,A25,管理表!AH:AH,"<>退職",管理表!J:J,C25,管理表!D:D,E25,管理表!C:C,"協同本社") -> 0 | K25: =COUNTIFS(管理表!N:N,A25,管理表!AH:AH,"<>退職",管理表!J:J,C25,管理表!D:D,E25,管理表!C:C,"津吉") -> 0
E26: インドネシア | F26: =COUNTIFS(管理表!N:N,A25,管理表!AH:AH,"<>退職",管理表!J:J,C25,管理表!D:D,E26) -> 0 | G26: =COUNTIFS(管理表!N:N,A25,管理表!AH:AH,"<>退職",管理表!J:J,C25,管理表!D:D,E26,管理表!Q:Q,"*実習*") -> 0 | H26: =COUNTIFS(管理表!N:N,A25,管理表!AH:AH,"<>退職",管理表!J:J,C25,管理表!D:D,E26,管理表!Q:Q,"*特定*") -> 0 | I26: =COUNTIFS(管理表!N:N,A25,管理表!AH:AH,"<>退職",管理表!J:J,C25,管理表!D:D,E26,管理表!C:C,"本社") -> 0 | J26: =COUNTIFS(管理表!N:N,A25,管理表!AH:AH,"<>退職",管理表!J:J,C25,管理表!D:D,E26,管理表!C:C,"協同本社") -> 0 | K26: =COUNTIFS(管理表!N:N,A25,管理表!AH:AH,"<>退職",管理表!J:J,C25,管理表!D:D,E26,管理表!C:C,"津吉") -> 0
C27: 女 | D27: =COUNTIFS(管理表!N:N,A25,管理表!AH:AH,"<>退職",管理表!J:J,C27) -> 7 | E27: ベトナム | F27: =COUNTIFS(管理表!N:N,A25,管理表!AH:AH,"<>退職",管理表!J:J,C27,管理表!D:D,E27) -> 7 | G27: =COUNTIFS(管理表!N:N,A25,管理表!AH:AH,"<>退職",管理表!J:J,C27,管理表!D:D,E27,管理表!Q:Q,"*実習*") -> 7 | H27: =COUNTIFS(管理表!N:N,A25,管理表!AH:AH,"<>退職",管理表!J:J,C27,管理表!D:D,E27,管理表!Q:Q,"*特定*") -> 0 | I27: =COUNTIFS(管理表!N:N,A25,管理表!AH:AH,"<>退職",管理表!J:J,C27,管理表!D:D,E27,管理表!C:C,"本社") -> 7 | J27: =COUNTIFS(管理表!N:N,A25,管理表!AH:AH,"<>退職",管理表!J:J,C27,管理表!D:D,E27,管理表!C:C,"協同本社") -> 0 | K27: =COUNTIFS(管理表!N:N,A25,管理表!AH:AH,"<>退職",管理表!J:J,C27,管理表!D:D,E27,管理表!C:C,"津吉") -> 0
E28: インドネシア | F28: =COUNTIFS(管理表!N:N,A25,管理表!AH:AH,"<>退職",管理表!J:J,C27,管理表!D:D,E28) -> 0 | G28: =COUNTIFS(管理表!N:N,A25,管理表!AH:AH,"<>退職",管理表!J:J,C27,管理表!D:D,E28,管理表!Q:Q,"*実習*") -> 0 | H28: =COUNTIFS(管理表!N:N,A25,管理表!AH:AH,"<>退職",管理表!J:J,C27,管理表!D:D,E28,管理表!Q:Q,"*特定*") -> 0 | I28: =COUNTIFS(管理表!N:N,A25,管理表!AH:AH,"<>退職",管理表!J:J,C27,管理表!D:D,E28,管理表!C:C,"本社") -> 0 | J28: =COUNTIFS(管理表!N:N,A25,管理表!AH:AH,"<>退職",管理表!J:J,C27,管理表!D:D,E28,管理表!C:C,"協同本社") -> 0 | K28: =COUNTIFS(管理表!N:N,A25,管理表!AH:AH,"<>退職",管理表!J:J,C27,管理表!D:D,E28,管理表!C:C,"津吉") -> 0
A29: デルタ四国 | B29: =COUNTIFS(管理表!N:N,A29,管理表!AH:AH,"<>退職") -> 3 | C29: 男 | D29: =COUNTIFS(管理表!N:N,A29,管理表!AH:AH,"<>退職",管理表!J:J,C29) -> 1 | E29: ベトナム | F29: =COUNTIFS(管理表!N:N,A29,管理表!AH:AH,"<>退職",管理表!J:J,C29,管理表!D:D,E29) -> 1 | G29: =COUNTIFS(管理表!N:N,A29,管理表!AH:AH,"<>退職",管理表!J:J,C29,管理表!D:D,E29,管理表!Q:Q,"*実習*") -> 0 | H29: =COUNTIFS(管理表!N:N,A29,管理表!AH:AH,"<>退職",管理表!J:J,C29,管理表!D:D,E29,管理表!Q:Q,"*特定*") -> 1 | I29: =COUNTIFS(管理表!N:N,A29,管理表!AH:AH,"<>退職",管理表!J:J,C29,管理表!D:D,E29,管理表!C:C,"本社") -> 0 | J29: =COUNTIFS(管理表!N:N,A29,管理表!AH:AH,"<>退職",管理表!J:J,C29,管理表!D:D,E29,管理表!C:C,"協同本社") -> 0 | K29: =COUNTIFS(管理表!N:N,A29,管理表!AH:AH,"<>退職",管理表!J:J,C29,管理表!D:D,E29,管理表!C:C,"津吉") -> 1
E30: インドネシア | F30: =COUNTIFS(管理表!N:N,A29,管理表!AH:AH,"<>退職",管理表!J:J,C29,管理表!D:D,E30) -> 0 | G30: =COUNTIFS(管理表!N:N,A29,管理表!AH:AH,"<>退職",管理表!J:J,C29,管理表!D:D,E30,管理表!Q:Q,"*実習*") -> 0 | H30: =COUNTIFS(管理表!N:N,A29,管理表!AH:AH,"<>退職",管理表!J:J,C29,管理表!D:D,E30,管理表!Q:Q,"*特定*") -> 0 | I30: =COUNTIFS(管理表!N:N,A29,管理表!AH:AH,"<>退職",管理表!J:J,C29,管理表!D:D,E30,管理表!C:C,"本社") -> 0 | J30: =COUNTIFS(管理表!N:N,A29,管理表!AH:AH,"<>退職",管理表!J:J,C29,管理表!D:D,E30,管理表!C:C,"協同本社") -> 0 | K30: =COUNTIFS(管理表!N:N,A29,管理表!AH:AH,"<>退職",管理表!J:J,C29,管理表!D:D,E30,管理表!C:C,"津吉") -> 0
C31: 女 | D31: =COUNTIFS(管理表!N:N,A29,管理表!AH:AH,"<>退職",管理表!J:J,C31) -> 2 | E31: ベトナム | F31: =COUNTIFS(管理表!N:N,A29,管理表!AH:AH,"<>退職",管理表!J:J,C31,管理表!D:D,E31) -> 2 | G31: =COUNTIFS(管理表!N:N,A29,管理表!AH:AH,"<>退職",管理表!J:J,C31,管理表!D:D,E31,管理表!Q:Q,"*実習*") -> 0 | H31: =COUNTIFS(管理表!N:N,A29,管理表!AH:AH,"<>退職",管理表!J:J,C31,管理表!D:D,E31,管理表!Q:Q,"*特定*") -> 2 | I31: =COUNTIFS(管理表!N:N,A29,管理表!AH:AH,"<>退職",管理表!J:J,C31,管理表!D:D,E31,管理表!C:C,"本社") -> 0 | J31: =COUNTIFS(管理表!N:N,A29,管理表!AH:AH,"<>退職",管理表!J:J,C31,管理表!D:D,E31,管理表!C:C,"協同本社") -> 0 | K31: =COUNTIFS(管理表!N:N,A29,管理表!AH:AH,"<>退職",管理表!J:J,C31,管理表!D:D,E31,管理表!C:C,"津吉") -> 2
E32: インドネシア | F32: =COUNTIFS(管理表!N:N,A29,管理表!AH:AH,"<>退職",管理表!J:J,C31,管理表!D:D,E32) -> 0 | G32: =COUNTIFS(管理表!N:N,A29,管理表!AH:AH,"<>退職",管理表!J:J,C31,管理表!D:D,E32,管理表!Q:Q,"*実習*") -> 0 | H32: =COUNTIFS(管理表!N:N,A29,管理表!AH:AH,"<>退職",管理表!J:J,C31,管理表!D:D,E32,管理表!Q:Q,"*特定*") -> 0 | I32: =COUNTIFS(管理表!N:N,A29,管理表!AH:AH,"<>退職",管理表!J:J,C31,管理表!D:D,E32,管理表!C:C,"本社") -> 0 | J32: =COUNTIFS(管理表!N:N,A29,管理表!AH:AH,"<>退職",管理表!J:J,C31,管理表!D:D,E32,管理表!C:C,"協同本社") -> 0 | K32: =COUNTIFS(管理表!N:N,A29,管理表!AH:AH,"<>退職",管理表!J:J,C31,管理表!D:D,E32,管理表!C:C,"津吉") -> 0
A33: 中四国 | B33: =COUNTIFS(管理表!N:N,A33,管理表!AH:AH,"<>退職") -> 37 | C33: 男 | D33: =COUNTIFS(管理表!N:N,A33,管理表!AH:AH,"<>退職",管理表!J:J,C33) -> 12 | E33: ベトナム | F33: =COUNTIFS(管理表!N:N,A33,管理表!AH:AH,"<>退職",管理表!J:J,C33,管理表!D:D,E33) -> 12 | G33: =COUNTIFS(管理表!N:N,A33,管理表!AH:AH,"<>退職",管理表!J:J,C33,管理表!D:D,E33,管理表!Q:Q,"*実習*") -> 4 | H33: =COUNTIFS(管理表!N:N,A33,管理表!AH:AH,"<>退職",管理表!J:J,C33,管理表!D:D,E33,管理表!Q:Q,"*特定*") -> 8 | I33: =COUNTIFS(管理表!N:N,A33,管理表!AH:AH,"<>退職",管理表!J:J,C33,管理表!D:D,E33,管理表!C:C,"本社") -> 9 | J33: =COUNTIFS(管理表!N:N,A33,管理表!AH:AH,"<>退職",管理表!J:J,C33,管理表!D:D,E33,管理表!C:C,"協同本社") -> 2 | K33: =COUNTIFS(管理表!N:N,A33,管理表!AH:AH,"<>退職",管理表!J:J,C33,管理表!D:D,E33,管理表!C:C,"津吉") -> 1
E34: インドネシア | F34: =COUNTIFS(管理表!N:N,A33,管理表!AH:AH,"<>退職",管理表!J:J,C33,管理表!D:D,E34) -> 0 | G34: =COUNTIFS(管理表!N:N,A33,管理表!AH:AH,"<>退職",管理表!J:J,C33,管理表!D:D,E34,管理表!Q:Q,"*実習*") -> 0 | H34: =COUNTIFS(管理表!N:N,A33,管理表!AH:AH,"<>退職",管理表!J:J,C33,管理表!D:D,E34,管理表!Q:Q,"*特定*") -> 0 | I34: =COUNTIFS(管理表!N:N,A33,管理表!AH:AH,"<>退職",管理表!J:J,C33,管理表!D:D,E34,管理表!C:C,"本社") -> 0 | J34: =COUNTIFS(管理表!N:N,A33,管理表!AH:AH,"<>退職",管理表!J:J,C33,管理表!D:D,E34,管理表!C:C,"協同本社") -> 0 | K34: =COUNTIFS(管理表!N:N,A33,管理表!AH:AH,"<>退職",管理表!J:J,C33,管理表!D:D,E34,管理表!C:C,"津吉") -> 0
C35: 女 | D35: =COUNTIFS(管理表!N:N,A33,管理表!AH:AH,"<>退職",管理表!J:J,C35) -> 25 | E35: ベトナム | F35: =COUNTIFS(管理表!N:N,A33,管理表!AH:AH,"<>退職",管理表!J:J,C35,管理表!D:D,E35) -> 25 | G35: =COUNTIFS(管理表!N:N,A33,管理表!AH:AH,"<>退職",管理表!J:J,C35,管理表!D:D,E35,管理表!Q:Q,"*実習*") -> 8 | H35: =COUNTIFS(管理表!N:N,A33,管理表!AH:AH,"<>退職",管理表!J:J,C35,管理表!D:D,E35,管理表!Q:Q,"*特定*") -> 17 | I35: =COUNTIFS(管理表!N:N,A33,管理表!AH:AH,"<>退職",管理表!J:J,C35,管理表!D:D,E35,管理表!C:C,"本社") -> 17 | J35: =COUNTIFS(管理表!N:N,A33,管理表!AH:AH,"<>退職",管理表!J:J,C35,管理表!D:D,E35,管理表!C:C,"協同本社") -> 2 | K35: =COUNTIFS(管理表!N:N,A33,管理表!AH:AH,"<>退職",管理表!J:J,C35,管理表!D:D,E35,管理表!C:C,"津吉") -> 6
E36: インドネシア | F36: =COUNTIFS(管理表!N:N,A33,管理表!AH:AH,"<>退職",管理表!J:J,C35,管理表!D:D,E36) -> 0 | G36: =COUNTIFS(管理表!N:N,A33,管理表!AH:AH,"<>退職",管理表!J:J,C35,管理表!D:D,E36,管理表!Q:Q,"*実習*") -> 0 | H36: =COUNTIFS(管理表!N:N,A33,管理表!AH:AH,"<>退職",管理表!J:J,C35,管理表!D:D,E36,管理表!Q:Q,"*特定*") -> 0 | I36: =COUNTIFS(管理表!N:N,A33,管理表!AH:AH,"<>退職",管理表!J:J,C35,管理表!D:D,E36,管理表!C:C,"本社") -> 0 | J36: =COUNTIFS(管理表!N:N,A33,管理表!AH:AH,"<>退職",管理表!J:J,C35,管理表!D:D,E36,管理表!C:C,"協同本社") -> 0 | K36: =COUNTIFS(管理表!N:N,A33,管理表!AH:AH,"<>退職",管理表!J:J,C35,管理表!D:D,E36,管理表!C:C,"津吉") -> 0
A37: H&C | B37: =COUNTIFS(管理表!N:N,A37,管理表!AH:AH,"<>退職") -> 77 | C37: 男 | D37: =COUNTIFS(管理表!N:N,A37,管理表!AH:AH,"<>退職",管理表!J:J,C37) -> 24 | E37: ベトナム | F37: =COUNTIFS(管理表!N:N,A37,管理表!AH:AH,"<>退職",管理表!J:J,C37,管理表!D:D,E37) -> 0 | G37: =COUNTIFS(管理表!N:N,A37,管理表!AH:AH,"<>退職",管理表!J:J,C37,管理表!D:D,E37,管理表!Q:Q,"*実習*") -> 0 | H37: =COUNTIFS(管理表!N:N,A37,管理表!AH:AH,"<>退職",管理表!J:J,C37,管理表!D:D,E37,管理表!Q:Q,"*特定*") -> 0 | I37: =COUNTIFS(管理表!N:N,A37,管理表!AH:AH,"<>退職",管理表!J:J,C37,管理表!D:D,E37,管理表!C:C,"本社") -> 0 | J37: =COUNTIFS(管理表!N:N,A37,管理表!AH:AH,"<>退職",管理表!J:J,C37,管理表!D:D,E37,管理表!C:C,"協同本社") -> 0 | K37: =COUNTIFS(管理表!N:N,A37,管理表!AH:AH,"<>退職",管理表!J:J,C37,管理表!D:D,E37,管理表!C:C,"津吉") -> 0
E38: インドネシア | F38: =COUNTIFS(管理表!N:N,A37,管理表!AH:AH,"<>退職",管理表!J:J,C37,管理表!D:D,E38) -> 24 | G38: =COUNTIFS(管理表!N:N,A37,管理表!AH:AH,"<>退職",管理表!J:J,C37,管理表!D:D,E38,管理表!Q:Q,"*実習*") -> 0 | H38: =COUNTIFS(管理表!N:N,A37,管理表!AH:AH,"<>退職",管理表!J:J,C37,管理表!D:D,E38,管理表!Q:Q,"*特定*") -> 24 | I38: =COUNTIFS(管理表!N:N,A37,管理表!AH:AH,"<>退職",管理表!J:J,C37,管理表!D:D,E38,管理表!C:C,"本社") -> 0 | J38: =COUNTIFS(管理表!N:N,A37,管理表!AH:AH,"<>退職",管理表!J:J,C37,管理表!D:D,E38,管理表!C:C,"協同本社") -> 0 | K38: =COUNTIFS(管理表!N:N,A37,管理表!AH:AH,"<>退職",管理表!J:J,C37,管理表!D:D,E38,管理表!C:C,"津吉") -> 24
C39: 女 | D39: =COUNTIFS(管理表!N:N,A37,管理表!AH:AH,"<>退職",管理表!J:J,C39) -> 53 | E39: ベトナム | F39: =COUNTIFS(管理表!N:N,A37,管理表!AH:AH,"<>退職",管理表!J:J,C39,管理表!D:D,E39) -> 0 | G39: =COUNTIFS(管理表!N:N,A37,管理表!AH:AH,"<>退職",管理表!J:J,C39,管理表!D:D,E39,管理表!Q:Q,"*実習*") -> 0 | H39: =COUNTIFS(管理表!N:N,A37,管理表!AH:AH,"<>退職",管理表!J:J,C39,管理表!D:D,E39,管理表!Q:Q,"*特定*") -> 0 | I39: =COUNTIFS(管理表!N:N,A37,管理表!AH:AH,"<>退職",管理表!J:J,C39,管理表!D:D,E39,管理表!C:C,"本社") -> 0 | J39: =COUNTIFS(管理表!N:N,A37,管理表!AH:AH,"<>退職",管理表!J:J,C39,管理表!D:D,E39,管理表!C:C,"協同本社") -> 0 | K39: =COUNTIFS(管理表!N:N,A37,管理表!AH:AH,"<>退職",管理表!J:J,C39,管理表!D:D,E39,管理表!C:C,"津吉") -> 0
E40: インドネシア | F40: =COUNTIFS(管理表!N:N,A37,管理表!AH:AH,"<>退職",管理表!J:J,C39,管理表!D:D,E40) -> 53 | G40: =COUNTIFS(管理表!N:N,A37,管理表!AH:AH,"<>退職",管理表!J:J,C39,管理表!D:D,E40,管理表!Q:Q,"*実習*") -> 0 | H40: =COUNTIFS(管理表!N:N,A37,管理表!AH:AH,"<>退職",管理表!J:J,C39,管理表!D:D,E40,管理表!Q:Q,"*特定*") -> 53 | I40: =COUNTIFS(管理表!N:N,A37,管理表!AH:AH,"<>退職",管理表!J:J,C39,管理表!D:D,E40,管理表!C:C,"本社") -> 0 | J40: =COUNTIFS(管理表!N:N,A37,管理表!AH:AH,"<>退職",管理表!J:J,C39,管理表!D:D,E40,管理表!C:C,"協同本社") -> 0 | K40: =COUNTIFS(管理表!N:N,A37,管理表!AH:AH,"<>退職",管理表!J:J,C39,管理表!D:D,E40,管理表!C:C,"津吉") -> 53
A41: INA | B41: =COUNTIFS(管理表!N:N,A41,管理表!AH:AH,"<>退職") -> 15 | C41: 男 | D41: =COUNTIFS(管理表!N:N,A41,管理表!AH:AH,"<>退職",管理表!J:J,C41) -> 3 | E41: ベトナム | F41: =COUNTIFS(管理表!N:N,A41,管理表!AH:AH,"<>退職",管理表!J:J,C41,管理表!D:D,E41) -> 0 | G41: =COUNTIFS(管理表!N:N,A41,管理表!AH:AH,"<>退職",管理表!J:J,C41,管理表!D:D,E41,管理表!Q:Q,"*実習*") -> 0 | H41: =COUNTIFS(管理表!N:N,A41,管理表!AH:AH,"<>退職",管理表!J:J,C41,管理表!D:D,E41,管理表!Q:Q,"*特定*") -> 0 | I41: =COUNTIFS(管理表!N:N,A41,管理表!AH:AH,"<>退職",管理表!J:J,C41,管理表!D:D,E41,管理表!C:C,"本社") -> 0 | J41: =COUNTIFS(管理表!N:N,A41,管理表!AH:AH,"<>退職",管理表!J:J,C41,管理表!D:D,E41,管理表!C:C,"協同本社") -> 0 | K41: =COUNTIFS(管理表!N:N,A41,管理表!AH:AH,"<>退職",管理表!J:J,C41,管理表!D:D,E41,管理表!C:C,"津吉") -> 0
...

Sheet 入社予定
A1: 区 | B1: No | C1: 勤務地 | D1: 国籍 | E1: 社員コード | F1: 写真 | G1: フリガナ | H1: 氏名 | I1: 呼名 | J1: 性別 | K1: 生年月日 | L1: 年齢 | M1: 配偶者 | N1: 登録支援機関 | O1: 入社日 | P1: 帰国予定 | Q1: 実習区分 | R1: 住所 | S1: 個・相部屋 | T1: 家賃負担 | U1: 雇用条件書 | V1: カード期限 | W1: 在留カード番号 | X1: 雇用保険番号 | Y1: 自転車渡日 | Z1: 自転車No-防犯 | AA1: 自転車回収日 | AB1: 日本語検定 | AC1: 試験資格 | AD1: 一時退職日 | AE1: 一時帰国From | AF1: 一時帰国To | AG1: 再入社 | AH1: 退職区分 | AI1: 退職日 | AJ1: 帰国費用 | AK1: 部署長 | AL1: 備考
C3: 本社 | D3: ベトナム | G3: チャン ティ シン | H3: TRAN THI SINH | J3: 女 | K3: 36088 | L3: =DATEDIF(K3,TODAY(),"Y") -> 27 | M3: 夫婦 | N3: 関東食肉 | O3: 2026/4月末頃 | P3: ライの妻 | Q3: 技能実習1号 | R3: 和泉北1-20-28アトムスカイマンション304 | S3: 相 | T3: 10000 | U3: 45726 | AL3: 2/18面接 合格 ライの奥さん
C4: 本社 | D4: ベトナム | G4: ダオ ティ トゥイ リン | H4: DAO THI THUY LINH | J4: 女 | K4: 39110 | L4: 19 | M4: 無 | N4: 関東食肉 | O4: 2026/2月末 ～3月頃 | P4: ゴックの妹 | Q4: 技能実習1号 | R4: 和泉北1-20-28アトムスカイマンション406 | S4: 個 | T4: ゴック、タオ 家賃どうするか | AL4: ゴックの妹
C6: 本社 | D6: ベトナム | G6: バン ティ タム | H6: BANG THI TAM | I6: バン | J6: 女 | K6: 37885 | L6: 22 | M6: 有 | N6: 中四国 | O6: 46143 | Q6: 技能実習1号 | R6: ハーさんの弟の奥さん ハーさんと同部屋希望 アトム401 | S6: 相 | T6: 10000 | AL6: 2025/9/22面接 合格
C10: 津吉 | D10: インドネシア | G10: アルム ムティアラ ヴァレンティネザ プトリ | H10: ARUM MUTIARA VALENTINEZA PUTRI | J10: 女 | K10: 35080 | L10: 30 | M10: 夫婦 | N10: 中温 | O10: 2026/5月頃 | Q10: 特定技能１号 | R10: ククの奥さん 松山市中野町442-1 | S10: 夫婦 | AL10: ククの奥さん
C11: 津吉 | D11: インドネシア | G11: アグス プラヨガ | H11: AGUS PRAYOGA | I11: ヨガ | J11: 男 | K11: 36119 | L11: 27 | M11: 夫婦 | N11: 中温 | O11: 2026/5月頃 | Q11: 特定技能１号 | R11: 松山市上野町774番地ビレッジハウス松山上野3ｰ508 | S11: 夫婦 | AL11: エヴィの夫
C12: 津吉 | D12: インドネシア | G12: ナスルル ファーミ | H12: NASRUL FAHMI | J12: 男 | K12: 35924 | L12: 27 | M12: 夫婦 | N12: 中温 | O12: 2026/5月頃 | Q12: 特定技能１号 | R12: ヌルアンディニの夫 松山市上野町774番地ビレッジハウス松山上野4-501 | S12: 夫婦 | AL12: ヌルアンディニの夫
D14: ベトナム | G14: グエン ティ フォアン マイ | H14: NGUYEN THI HOANG MAI | J14: 女 | K14: 38635 | L14: =DATEDIF(K14,TODAY(),"Y") -> 20 | N14: 中温 | Q14: 特定活動告示9号
D15: ベトナム | G15: ゴー グエン トゥエット バン | H15: NGO NGUYEN TUYET BANG | J15: 女 | K15: 38130 | L15: =DATEDIF(K15,TODAY(),"Y") -> 21 | N15: 中温 | Q15: 特定活動告示9号
D16: ベトナム | G16: ホー ティ ホン アン | H16: HO THI HONG AN | J16: 女 | K16: 38295 | L16: =DATEDIF(K16,TODAY(),"Y") -> 21 | N16: 中温 | Q16: 特定活動告示9号
D17: ベトナム | G17: グエン ファム トゥオン ヴィ | H17: NGUYEN PHAM TUONG VY | J17: 女 | K17: 38321 | L17: =DATEDIF(K17,TODAY(),"Y") -> 21 | N17: 中温 | Q17: 特定活動告示9号
D18: ベトナム | G18: ダン ティ ゴック ヴァン | H18: DANG THI NGOC VANG | J18: 女 | K18: 38692 | L18: =DATEDIF(K18,TODAY(),"Y") -> 20 | N18: 中温 | Q18: 特定活動告示9号
D19: ベトナム | G19: ダン ティ トゥイ アイン | H19: DANG THI THUY ANH | J19: 女 | K19: 38288 | L19: =DATEDIF(K19,TODAY(),"Y") -> 21 | N19: 中温 | Q19: 特定活動告示9号
D20: ベトナム | G20: ホー ティ ホン トム | H20: HO THI HONG THOM | J20: 女 | K20: 38631 | L20: =DATEDIF(K20,TODAY(),"Y") -> 20 | N20: 中温 | Q20: 特定活動告示9号
D21: ベトナム | G21: グエン レー スアン ハイン | H21: NGUYEN LE XUAN HANH | J21: 女 | K21: 38032 | L21: =DATEDIF(K21,TODAY(),"Y") -> 22 | N21: 中温 | Q21: 特定活動告示9号
D22: ベトナム | G22: ゴー ミ アイン | H22: NGO MY ANH | J22: 女 | K22: 38355 | L22: =DATEDIF(K22,TODAY(),"Y") -> 21 | N22: 中温 | Q22: 特定活動告示9号
D23: ベトナム | G23: チャン グエン カ ハン | H23: TRAN NGUYEN KHA HAN | J23: 女 | K23: 38234 | L23: =DATEDIF(K23,TODAY(),"Y") -> 21 | N23: 中温 | Q23: 特定活動告示9号
D24: ベトナム | G24: チュオン ゴック ジェップ | H24: TRUONG NGOC DIEP | J24: 女 | K24: 38513 | L24: =DATEDIF(K24,TODAY(),"Y") -> 20 | N24: 中温 | Q24: 特定活動告示9号
D25: ベトナム | G25: グエン フォン ガン | H25: NGUYEN PHUONG NGAN | J25: 女 | K25: 38655 | L25: =DATEDIF(K25,TODAY(),"Y") -> 20 | N25: 中温 | Q25: 特定活動告示9号
C27: 津吉 | D27: インドネシア | G27: バングン ケダトン | H27: BANGUN KEDHATON | J27: 男 | K27: 37439 | L27: 23 | N27: 中温 | Q27: 特定技能１号 | R27: レイハン友人つながり
C28: 津吉 | D28: インドネシア | G28: アクマル クルニアワン | H28: AKMAL KURNIAWAN | J28: 男 | K28: 37928 | L28: 22 | N28: 中温 | Q28: 特定技能１号 | R28: レイハン友人 | AL28: 4/8面接 合格
C29: 津吉 | D29: インドネシア | G29: ムハッマド イマム アル フィトリ | H29: MUHAMMAD IMAM AL FITRI | J29: 男 | K29: 37950 | L29: 22 | N29: 中温 | Q29: 特定技能１号 | R29: レイハン友人 | AL29: 4/8面接 合格
C30: 津吉 | D30: インドネシア | G30: ハリ テグ プラセティオ | H30: HARI TEGUH PRASETIO | J30: 男 | K30: 37428 | L30: 23 | N30: 中温 | Q30: 特定技能１号 | R30: エヴィ夫 友人 | AL30: 4/8面接 合格
C31: 津吉 | D31: インドネシア | G31: アリファ ハフィゾトゥン ハサナ | H31: ALIFAH HAFIZHOTUN HASANAH | J31: 女 | K31: 37856 | L31: 22 | N31: 中温 | Q31: 特定技能１号 | R31: サエ 友人 | AL31: 4/13面接 合格
C32: 津吉 | D32: インドネシア | G32: トリ ヌル インダー レスタリ | H32: TRI NUR INDAH LESTARI | J32: 女 | K32: 38591 | L32: 20 | N32: 中温 | Q32: 特定技能１号 | R32: アイシャ、エヴィ 友人 | AL32: 4/13面接 合格
A34: R | C34: 津吉 | D34: インドネシア | G34: イルハム マウラナ | H34: ILHAM MAULANA | I34: イルハム | J34: 男 | K34: 36320 | L34: 26 | M34: 無 | O34: 46023 | Q34: 特定技能１号 | R34: 中野町457-1 | S34: 相 | U34: 45778 | AL34: 4/25面接 合格
A35: R | C35: 津吉 | D35: インドネシア | G35: リヴォ デャルマザル | H35: RIVO DHARMAZAL | I35: リヴォ | J35: 男 | K35: 37822 | L35: 22 | M35: 無 | O35: 46023 | Q35: 特定技能１号 | S35: 相 | U35: 45778 | AL35: 4/25面接 合格
A36: R | C36: 津吉 | D36: インドネシア | G36: アルディアヌス バワメネウィ | H36: ARDIANUS BAWAMENEWI | I36: アルディ | J36: 男 | K36: 36228 | L36: 26 | M36: 無 | O36: 46023 | Q36: 特定技能１号 | S36: 相 | U36: 45778 | AL36: 4/25面接 合格
A37: R | C37: 津吉 | D37: インドネシア | G37: エム フィクリ イクサン | H37: M. FIKRI IKHSAN | I37: フィクリ | J37: 男 | K37: 38361 | L37: 21 | M37: 無 | O37: 46023 | Q37: 特定技能１号 | S37: 相 | U37: 45778 | AL37: 4/25面接 合格
A38: R | C38: 津吉 | D38: インドネシア | G38: ヒクマル ハナフィス | H38: HIKMAL HANAFIS | I38: ヒクマル | J38: 男 | K38: 38534 | L38: 20 | M38: 無 | O38: 46023 | Q38: 特定技能１号 | R38: 中野町457-1 | S38: 相 | U38: 45778 | AL38: 4/25面接 合格
A39: R | C39: 津吉 | D39: インドネシア | G39: フェルナ マルヤニ | H39: FERNA MARYANI | I39: フェルナ | J39: 女 | K39: 37302 | L39: 23 | M39: 無 | O39: 46023 | Q39: 特定技能１号 | R39: 東温市牛渕170-３ | S39: 相 | U39: 45778 | AL39: 4/25面接 合格
A40: R | C40: 津吉 | D40: インドネシア | G40: エラ マルリアナ リヤンティ | H40: ELA MARLIANA RIYANTI | I40: エラ | J40: 女 | K40: 36977 | L40: 24 | M40: 無 | O40: 46023 | Q40: 特定技能１号 | R40: 東温市牛渕170-３ | S40: 相 | U40: 45778 | AL40: 4/25面接 合格
A41: R | C41: 津吉 | D41: インドネシア | G41: ファンニ ヨランダ | H41: FANNY YOLANDA | I41: ファンニ | J41: 女 | K41: 35581 | L41: 28 | M41: 無 | O41: 46023 | Q41: 特定技能１号 | R41: 東温市牛渕170-３ | S41: 相 | U41: 45778 | AL41: 4/25面接 合格
A42: R | C42: 津吉 | D42: インドネシア | G42: リディア アフィザ | H42: LIDYA AFIZA | I42: リディア | J42: 女 | K42: 35156 | L42: 29 | M42: 無 | O42: 46023 | Q42: 特定技能１号 | R42: 東温市牛渕170-３ | S42: 相 | U42: 45778 | AL42: 4/25面接 合格
A43: R | C43: 津吉 | D43: インドネシア | G43: セプティ エカ ドウィジャヤンティ | H43: SEPTI EKA DWIJAYANTI | I43: エカ | J43: 女 | K43: 38239 | L43: 21 | M43: 無 | O43: 46023 | Q43: 特定技能１号 | R43: 東温市牛渕170-３ | S43: 相 | U43: 45778 | AL43: 4/25面接 合格
A44: R | C44: 津吉 | D44: インドネシア | G44: デフィアナ レトノワティ | H44: DEVIANA RETNOWATI | I44: レトノ | J44: 女 | K44: 36613 | L44: 25 | M44: 無 | O44: 46023 | Q44: 特定技能１号 | R44: 東温市牛渕170-３ | S44: 相 | U44: 45778 | AL44: 4/25面接 合格
A45: R | C45: 津吉 | D45: インドネシア | G45: ムハマド バユ アセガフ | H45: MUHAMMAD BAYU ASSEGAF | I45: バユ | J45: 男 | K45: 38352 | L45: 21 | M45: 無 | O45: 46023 | Q45: 特定技能１号 | R45: 中野① 3人 or中野② 7人 | S45: 相 | U45: 45778 | AL45: 4/25面接 合格
A46: R | C46: 津吉 | D46: インドネシア | G46: アディ プラタマ マウルディ | H46: ADI PRATAMA MAULUDY | I46: アディ | J46: 男 | K46: 35637 | L46: 28 | M46: 無 | O46: 46023 | Q46: 特定技能１号 | S46: 相 | U46: 45778 | AL46: 4/25面接 合格
A47: R | C47: 津吉 | D47: インドネシア | G47: フィルサン アヌグラー | H47: FIRSAN ANUGRAH | I47: フィルサン | J47: 男 | K47: 37311 | L47: 23 | M47: 無 | O47: 46023 | Q47: 特定技能１号 | S47: 相 | U47: 45778 | AL47: 4/25面接 合格
A48: R | C48: 津吉 | D48: インドネシア | G48: スルヤ アンガ ジャテサプトラ | H48: SURYA ANGGA JATISAPUTRA | I48: アンガ | J48: 男 | K48: 38238 | L48: 21 | M48: 無 | O48: 46023 | Q48: 特定技能１号 | S48: 相 | U48: 45778 | AL48: 4/25面接 合格
...

Sheet リーダー・副
A3: 特定生リーダー・副リーダー候補
B5: （工場長。部署長推薦） | H5: 45612
A7: 部署名 | D7: 社員ＣＤ | E7: 氏名 | H7: 入社年月日 | J7: 在籍年月
A8: 製造一課 | C8: リーダー | D8: 07001609 | E8: マイン(男性) | H8: 2020.10.15 | J8: 5年
C9: リーダー | D9: 07001607 | E9: ドー (男性) | H9: 2021.01.25 | J9: 4年
C10: 副リーダー | D10: 07001613 | E10: ロアン(女性) | H10: 2018.12.01 | J10: 7年
C11: 副リーダー | D11: 07001611 | E11: ミン (女性) | H11: 2018.12.01 | J11: 7年
A12: 製造二課 | C12: リーダー | D12: 07001605 | E12: ヴィエット(男性) | H12: 2020.10.15 | J12: 5年
C13: 副リーダー | D13: 07001614 | E13: チャン (女性) | H13: 2019.06.11 | J13: 6年
A14: 製造三課 | C14: リーダー | D14: 07001610 | E14: ダット(男性) | H14: 2020.10.15 | J14: 5年
C15: 副リーダー | D15: 07004416 | E15: ヒエン(女性) | H15: 2019.06.11 | J15: 4年 | L15: ※出産のため2023年6月一時帰国中。2025年2月再入社予定
A19: 特定生リーダー・副リーダー候補
B21: （工場長。部署長推薦） | I21: 45730
A23: 部署名 | D23: 社員ＣＤ | E23: 氏名 | H23: 性別 | I23: 入社年月日 | K23: 在籍年月 | M23: 国籍
A24: 製造第一課 Aライン | D24: 07011602 | E24: グエンビックフーン | H24: 女性 | I24: 43040 | K24: （7年） | M24: ベトナム
A25: 製造第一課 Bライン | D25: 07012602 | E25: チャンティートゥータオ | H25: 女性 | I25: 44566 | K25: （2年10カ月） | M25: ベトナム
A26: 製造第一課 Ｃライン | D26: 07011613 | E26: ファムティ チン | H26: 女性 | I26: 43729 | K26: （5年） | M26: ベトナム
A27: 製造第一課 Ｃライン | D27: 07013628 | E27: アリ クスナディ | H27: 男性 | I27: 44937 | K27: （1年11カ月） | M27: インドネシア
A28: 製造第一課 Dライン | D28: 07012601 | E28: ブィ ヒュウ フン | H28: 男性 | I28: 44566 | K28: （2年10カ月） | M28: ベトナム
A29: 製造第一課 Dライン | D29: 07013606 | E29: アユサヌルフィトリヤニ | H29: 女性 | I29: 44669 | K29: （2年7カ月） | M29: インドネシア
A30: 製造第二課 | D30: 07013619 | E30: ミフタフル アリフ | H30: 男性 | I30: 44669 | K30: （2年7カ月） | M30: インドネシア
A31: 製造第四課 | D31: 07013605 | E31: エヴィ ラハユ | H31: 女性 | I31: 44669 | K31: （2年7カ月） | M31: インドネシア
A32: 製造第四課 | D32: 07013601 | E32: トリ ユニ | H32: 女性 | I32: 44669 | K32: （2年7カ月） | M32: インドネシア
A33: 製造第四課 | D33: 07013635 | E33: レイハンアリサハシカザカリ | H33: 男性 | I33: 45027 | K33: （1年7カ月） | M33: インドネシア
A34: 製造第四課 | D34: 07013634 | E34: シャールル アルル | H34: 男性 | I34: 45027 | K34: （1年7カ月） | M34: インドネシア
A35: 製品管理課（箱入） | D35: 07011606 | E35: ヴーティ ホアン | H35: 女性 | I35: 44013 | K35: （3年7カ月） | M35: ベトナム | O35: ※1回退職、再入社
A36: 製品管理課（出荷） | D36: 07013626 | E36: ムハマンドナウファルアリムフタル | H36: 男性 | I36: 44937 | K36: （1年11カ月） | M36: インドネシア
